2022-02-16 14:38:30 WARNING (SyncWorker_0) [homeassistant.loader] We found a custom integration lovelace_gen which has not been tested by Home Assistant. This component might cause stability problems, be sure to disable it if you experience issues with Home Assistant
2022-02-16 14:38:30 ERROR (SyncWorker_0) [homeassistant.loader] The custom integration 'lovelace_gen' does not have a version key in the manifest file and was blocked from loading. See https://developers.home-assistant.io/blog/2021/01/29/custom-integration-changes#versions for more details
2022-02-16 14:38:30 WARNING (SyncWorker_2) [homeassistant.loader] We found a custom integration braviatv_psk which has not been tested by Home Assistant. This component might cause stability problems, be sure to disable it if you experience issues with Home Assistant
2022-02-16 14:38:30 WARNING (SyncWorker_1) [homeassistant.loader] We found a custom integration spotify-playlist-sensor which has not been tested by Home Assistant. This component might cause stability problems, be sure to disable it if you experience issues with Home Assistant
2022-02-16 14:38:30 ERROR (SyncWorker_1) [homeassistant.loader] The custom integration 'spotify-playlist-sensor' does not have a version key in the manifest file and was blocked from loading. See https://developers.home-assistant.io/blog/2021/01/29/custom-integration-changes#versions for more details
2022-02-16 14:38:30 WARNING (SyncWorker_3) [homeassistant.loader] We found a custom integration smartthinq_sensors which has not been tested by Home Assistant. This component might cause stability problems, be sure to disable it if you experience issues with Home Assistant
2022-02-16 14:38:30 WARNING (SyncWorker_4) [homeassistant.loader] We found a custom integration plex_recently_added which has not been tested by Home Assistant. This component might cause stability problems, be sure to disable it if you experience issues with Home Assistant
2022-02-16 14:38:30 WARNING (SyncWorker_5) [homeassistant.loader] We found a custom integration radarr_upcoming_media which has not been tested by Home Assistant. This component might cause stability problems, be sure to disable it if you experience issues with Home Assistant
2022-02-16 14:38:30 WARNING (SyncWorker_0) [homeassistant.loader] We found a custom integration sonarr_upcoming_media which has not been tested by Home Assistant. This component might cause stability problems, be sure to disable it if you experience issues with Home Assistant
2022-02-16 14:38:30 WARNING (SyncWorker_1) [homeassistant.loader] We found a custom integration powercalc which has not been tested by Home Assistant. This component might cause stability problems, be sure to disable it if you experience issues with Home Assistant
2022-02-16 14:38:30 WARNING (SyncWorker_7) [homeassistant.loader] We found a custom integration start_time which has not been tested by Home Assistant. This component might cause stability problems, be sure to disable it if you experience issues with Home Assistant
2022-02-16 14:38:30 WARNING (SyncWorker_8) [homeassistant.loader] We found a custom integration alexa_media which has not been tested by Home Assistant. This component might cause stability problems, be sure to disable it if you experience issues with Home Assistant
2022-02-16 14:38:30 WARNING (SyncWorker_6) [homeassistant.loader] We found a custom integration aquaariston which has not been tested by Home Assistant. This component might cause stability problems, be sure to disable it if you experience issues with Home Assistant
2022-02-16 14:38:30 WARNING (SyncWorker_4) [homeassistant.loader] We found a custom integration spotcast which has not been tested by Home Assistant. This component might cause stability problems, be sure to disable it if you experience issues with Home Assistant
2022-02-16 14:38:30 WARNING (SyncWorker_2) [homeassistant.loader] We found a custom integration amazon_rekognition which has not been tested by Home Assistant. This component might cause stability problems, be sure to disable it if you experience issues with Home Assistant
2022-02-16 14:38:30 WARNING (SyncWorker_10) [homeassistant.loader] We found a custom integration hacs which has not been tested by Home Assistant. This component might cause stability problems, be sure to disable it if you experience issues with Home Assistant
2022-02-16 14:38:30 WARNING (SyncWorker_3) [homeassistant.loader] We found a custom integration nuki_ng which has not been tested by Home Assistant. This component might cause stability problems, be sure to disable it if you experience issues with Home Assistant
2022-02-16 14:38:30 WARNING (SyncWorker_9) [homeassistant.loader] We found a custom integration car_wash which has not been tested by Home Assistant. This component might cause stability problems, be sure to disable it if you experience issues with Home Assistant
2022-02-16 14:38:30 WARNING (SyncWorker_5) [homeassistant.loader] We found a custom integration tahoma which has not been tested by Home Assistant. This component might cause stability problems, be sure to disable it if you experience issues with Home Assistant
2022-02-16 14:38:32 WARNING (MainThread) [homeassistant.config_entries] Config entry '192.168.1.51' for adguard integration not ready yet: Error occurred while communicating with AdGuard Home.; Retrying in background
2022-02-16 14:38:33 WARNING (MainThread) [homeassistant.helpers.entity] Entity binary_sensor.aqua_ariston_online (<class 'custom_components.aquaariston.binary_sensor.AristonAquaBinarySensor'>) implements device_state_attributes. Please report it to the custom component author.
2022-02-16 14:38:33 WARNING (MainThread) [homeassistant.config_entries] Config entry 'apt21hassio@gmail.com' for tahoma integration not ready yet: Failed to connect; Retrying in background
2022-02-16 14:38:33 ERROR (MainThread) [homeassistant.components.sensor] Platform esphome does not generate unique IDs. ID dallas-0000000000000000 already exists - ignoring sensor.q1_quinled_deca_temp
2022-02-16 14:38:33 ERROR (MainThread) [homeassistant.components.sensor] Platform esphome does not generate unique IDs. ID dallas-0000000000000000 already exists - ignoring sensor.q1_quinled_deca_temp
2022-02-16 14:38:35 WARNING (MainThread) [homeassistant.helpers.entity] Entity binary_sensor.aqua_ariston_antilegionella (<class 'custom_components.aquaariston.binary_sensor.AristonAquaBinarySensor'>) implements device_state_attributes. Please report it to the custom component author.
2022-02-16 14:38:35 WARNING (MainThread) [homeassistant.helpers.entity] Entity binary_sensor.aqua_ariston_changing_data_ongoing (<class 'custom_components.aquaariston.binary_sensor.AristonAquaBinarySensor'>) implements device_state_attributes. Please report it to the custom component author.
2022-02-16 14:38:35 WARNING (MainThread) [homeassistant.helpers.entity] Entity binary_sensor.aqua_ariston_eco (<class 'custom_components.aquaariston.binary_sensor.AristonAquaBinarySensor'>) implements device_state_attributes. Please report it to the custom component author.
2022-02-16 14:38:35 WARNING (MainThread) [homeassistant.helpers.entity] Entity binary_sensor.aqua_ariston_heating (<class 'custom_components.aquaariston.binary_sensor.AristonAquaBinarySensor'>) implements device_state_attributes. Please report it to the custom component author.
2022-02-16 14:38:35 WARNING (MainThread) [homeassistant.helpers.entity] Entity binary_sensor.aqua_ariston_power (<class 'custom_components.aquaariston.binary_sensor.AristonAquaBinarySensor'>) implements device_state_attributes. Please report it to the custom component author.
2022-02-16 14:38:36 WARNING (MainThread) [homeassistant.helpers.entity] Entity sensor.aqua_ariston_current_temperature (<class 'custom_components.aquaariston.sensor.AristonAquaSensor'>) implements device_state_attributes. Please report it to the custom component author.
2022-02-16 14:38:36 WARNING (MainThread) [homeassistant.helpers.entity] Entity sensor.aqua_ariston_mode (<class 'custom_components.aquaariston.sensor.AristonAquaSensor'>) implements device_state_attributes. Please report it to the custom component author.
2022-02-16 14:38:36 WARNING (MainThread) [homeassistant.helpers.entity] Entity sensor.aqua_ariston_time_left_to_heat (<class 'custom_components.aquaariston.sensor.AristonAquaSensor'>) implements device_state_attributes. Please report it to the custom component author.
2022-02-16 14:38:36 WARNING (MainThread) [homeassistant.helpers.entity] Entity sensor.aqua_ariston_required_temperature (<class 'custom_components.aquaariston.sensor.AristonAquaSensor'>) implements device_state_attributes. Please report it to the custom component author.
2022-02-16 14:38:36 WARNING (MainThread) [homeassistant.helpers.entity] Entity sensor.aqua_ariston_average_showers (<class 'custom_components.aquaariston.sensor.AristonAquaSensor'>) implements device_state_attributes. Please report it to the custom component author.
2022-02-16 14:38:36 WARNING (MainThread) [homeassistant.helpers.entity] Entity sensor.aqua_ariston_temperature_mode (<class 'custom_components.aquaariston.sensor.AristonAquaSensor'>) implements device_state_attributes. Please report it to the custom component author.
2022-02-16 14:38:37 WARNING (MainThread) [aioesphomeapi.reconnect_logic] Can't connect to ESPHome API for bedroom_bed_esp @ 192.168.1.27: Error connecting to ('192.168.1.27', 6053): [Errno 113] Connect call failed ('192.168.1.27', 6053)
2022-02-16 14:38:37 WARNING (MainThread) [aioesphomeapi.reconnect_logic] Can't connect to ESPHome API for samsung-ac-remote-control @ 192.168.1.25: Error connecting to ('192.168.1.25', 6053): [Errno 113] Connect call failed ('192.168.1.25', 6053)
2022-02-16 14:38:37 WARNING (MainThread) [aioesphomeapi.reconnect_logic] Can't connect to ESPHome API for livingroom_ceiling_led @ 192.168.1.97: Error connecting to ('192.168.1.97', 6053): [Errno 113] Connect call failed ('192.168.1.97', 6053)
2022-02-16 14:38:58 WARNING (MainThread) [homeassistant.helpers.entity] Entity sensor.aqua_ariston_required_showers (<class 'custom_components.aquaariston.sensor.AristonAquaSensor'>) implements device_state_attributes. Please report it to the custom component author.
2022-02-16 14:38:58 WARNING (MainThread) [homeassistant.helpers.entity] Entity water_heater.aqua_ariston (<class 'custom_components.aquaariston.water_heater.AristonAquaWaterHeater'>) implements device_state_attributes. Please report it to the custom component author.
2022-02-16 14:39:09 WARNING (MainThread) [homeassistant.components.automation.office_wardrobe_lights_by_door_sensors] Office Wardrobe Lights By Door sensors: Already running
2022-02-16 14:39:09 WARNING (MainThread) [homeassistant.components.automation.toggle_the_main_light_based_on_door_sensor] Toggle the main light based on door sensor: Already running
2022-02-16 14:39:09 ERROR (MainThread) [homeassistant.components.automation.office_closet_lights_toggle_by_door] Office Closet Lights Toggle By Door: Error executing script. Service not found for call_service at pos 1: Unable to find service light.turn_unknown
2022-02-16 14:39:09 ERROR (MainThread) [homeassistant.components.automation.office_closet_lights_toggle_by_door] Office Closet Lights Toggle By Door: Error executing script. Service not found for call_service at pos 1: Unable to find service light.turn_unknown
2022-02-16 14:39:09 WARNING (MainThread) [homeassistant.components.automation.kitchen_water_leak_warning] Kitchen Water Leak Warning: Already running
2022-02-16 14:39:09 ERROR (MainThread) [homeassistant.components.automation.office_closet_lights_toggle_by_door] Error while executing automation automation.office_closet_lights_toggle_by_door: Unable to find service light.turn_unknown
2022-02-16 14:39:09 ERROR (MainThread) [homeassistant.components.automation.office_closet_lights_toggle_by_door] Error while executing automation automation.office_closet_lights_toggle_by_door: Unable to find service light.turn_unknown
2022-02-16 14:39:09 WARNING (MainThread) [homeassistant.components.automation.office_wardrobe_lights_by_door_sensors] Office Wardrobe Lights By Door sensors: Already running
2022-02-16 14:39:09 ERROR (MainThread) [homeassistant.components.automation.office_closet_lights_toggle_by_door] Office Closet Lights Toggle By Door: Error executing script. Service not found for call_service at pos 1: Unable to find service light.turn_unknown
2022-02-16 14:39:09 ERROR (MainThread) [homeassistant.components.automation.office_closet_lights_toggle_by_door] Error while executing automation automation.office_closet_lights_toggle_by_door: Unable to find service light.turn_unknown
2022-02-16 14:39:09 ERROR (MainThread) [homeassistant.components.automation.office_closet_lights_toggle_by_door] Office Closet Lights Toggle By Door: Error executing script. Service not found for call_service at pos 1: Unable to find service light.turn_unknown
2022-02-16 14:39:09 ERROR (MainThread) [homeassistant.components.automation.office_closet_lights_toggle_by_door] Error while executing automation automation.office_closet_lights_toggle_by_door: Unable to find service light.turn_unknown
2022-02-16 14:39:22 WARNING (MainThread) [homeassistant.helpers.entity] Entity sensor.aqua_ariston_antilegionella_temperature (<class 'custom_components.aquaariston.sensor.AristonAquaSensor'>) implements device_state_attributes. Please report it to the custom component author.
2022-02-16 14:39:46 WARNING (MainThread) [homeassistant.helpers.entity] Entity sensor.aqua_ariston_active_errors (<class 'custom_components.aquaariston.sensor.AristonAquaSensor'>) implements device_state_attributes. Please report it to the custom component author.
2022-02-16 14:40:10 WARNING (MainThread) [homeassistant.helpers.entity] Entity sensor.aqua_ariston_time_program (<class 'custom_components.aquaariston.sensor.AristonAquaSensor'>) implements device_state_attributes. Please report it to the custom component author.
2022-02-16 14:42:35 WARNING (MainThread) [homeassistant.helpers.entity] Entity sensor.aqua_ariston_energy_use_in_the_last_day (<class 'custom_components.aquaariston.sensor.AristonAquaSensor'>) implements device_state_attributes. Please report it to the custom component author.
2022-02-16 14:42:35 WARNING (MainThread) [homeassistant.helpers.entity] Entity sensor.aqua_ariston_energy_use_in_the_last_month (<class 'custom_components.aquaariston.sensor.AristonAquaSensor'>) implements device_state_attributes. Please report it to the custom component author.
2022-02-16 14:42:35 WARNING (MainThread) [homeassistant.helpers.entity] Entity sensor.aqua_ariston_energy_use_in_the_last_week (<class 'custom_components.aquaariston.sensor.AristonAquaSensor'>) implements device_state_attributes. Please report it to the custom component author.
2022-02-16 14:42:35 WARNING (MainThread) [homeassistant.helpers.entity] Entity sensor.aqua_ariston_energy_use_in_the_last_year (<class 'custom_components.aquaariston.sensor.AristonAquaSensor'>) implements device_state_attributes. Please report it to the custom component author.
2022-02-16 14:43:36 WARNING (MainThread) [homeassistant.helpers.service] Unable to find referenced entities switch.bedroom_wardrobe_pre_trafo, switch.kitchen_pre_trafo_working_desk_light, switch.kitchen_stove, switch.living_room_below_tv_led_pre_trafo, switch.office_pre_trafo_wardrobe
2022-02-16 14:44:31 WARNING (MainThread) [homeassistant.helpers.service] Unable to find referenced entities scene.warning_lights
2022-02-16 14:44:31 WARNING (MainThread) [homeassistant.helpers.service] Unable to find referenced entities scene.all_lights
2022-02-16 14:44:57 WARNING (MainThread) [homeassistant.helpers.entity] Entity binary_sensor.aqua_ariston_update_available (<class 'custom_components.aquaariston.binary_sensor.AristonAquaBinarySensor'>) implements device_state_attributes. Please report it to the custom component author.
2022-02-16 14:47:04 ERROR (MainThread) [aiohttp.server] Error handling request
Traceback (most recent call last):
  File "/usr/local/lib/python3.9/site-packages/aiohttp/web_protocol.py", line 435, in _handle_request
    resp = await request_handler(request)
  File "/usr/local/lib/python3.9/site-packages/aiohttp/web_app.py", line 504, in _handle
    resp = await handler(request)
  File "/usr/local/lib/python3.9/site-packages/aiohttp/web_middlewares.py", line 117, in impl
    return await handler(request)
  File "/usr/src/homeassistant/homeassistant/components/http/security_filter.py", line 60, in security_filter_middleware
    return await handler(request)
  File "/usr/src/homeassistant/homeassistant/components/http/forwarded.py", line 98, in forwarded_middleware
    return await handler(request)
  File "/usr/src/homeassistant/homeassistant/components/http/request_context.py", line 28, in request_context_middleware
    return await handler(request)
  File "/usr/src/homeassistant/homeassistant/components/http/ban.py", line 79, in ban_middleware
    return await handler(request)
  File "/usr/src/homeassistant/homeassistant/components/http/auth.py", line 219, in auth_middleware
    return await handler(request)
  File "/usr/src/homeassistant/homeassistant/components/http/view.py", line 137, in handle
    result = await result
  File "/usr/src/homeassistant/homeassistant/components/image/__init__.py", line 194, in get
    await hass.async_add_executor_job(
  File "/usr/local/lib/python3.9/concurrent/futures/thread.py", line 52, in run
    result = self.fn(*self.args, **self.kwargs)
  File "/usr/src/homeassistant/homeassistant/components/image/__init__.py", line 210, in _generate_thumbnail
    image = ImageOps.exif_transpose(Image.open(original_path))
  File "/usr/local/lib/python3.9/site-packages/PIL/Image.py", line 2953, in open
    fp = builtins.open(filename, "rb")
FileNotFoundError: [Errno 2] No such file or directory: '/config/image/b46152742f1a261655cb02d8e9e671e5/original'
2022-02-16 14:47:06 ERROR (MainThread) [frontend.js.latest.202202030] http://192.168.1.79:8123/frontend_latest/729f9b9d.js:1:351 Uncaught RangeError: Value need to be finite number for Intl.RelativeTimeFormat.prototype.format()
2022-02-16 15:15:54 WARNING (MainThread) [homeassistant.helpers.template] Template variable warning: 'source' is undefined when rendering '{{ source }}'
2022-02-16 15:15:54 ERROR (MainThread) [homeassistant.components.denonavr.media_player] Command async_select_source failed with error: No mapping for input source 
2022-02-16 15:17:07 WARNING (MainThread) [homeassistant.components.automation.toggle_the_main_light_based_on_door_sensor] Toggle the main light based on door sensor: Already running
2022-02-16 15:17:10 WARNING (MainThread) [homeassistant.components.automation.toggle_the_main_light_based_on_door_sensor] Toggle the main light based on door sensor: Already running
2022-02-16 15:30:31 ERROR (stream_worker) [homeassistant.components.stream.stream.camera.despota_stefana] Error from stream worker: Stream ended; no additional packets
2022-02-16 15:30:34 ERROR (stream_worker) [homeassistant.components.stream.stream.camera.takovska] Error from stream worker: Stream ended; no additional packets
2022-02-16 15:30:35 ERROR (stream_worker) [homeassistant.components.stream.stream.camera.most_gazela] Error from stream worker: Stream ended; no additional packets
2022-02-16 15:30:39 ERROR (stream_worker) [homeassistant.components.stream.stream.camera.bogoslovija] Error from stream worker: Stream ended; no additional packets
2022-02-16 15:30:48 ERROR (stream_worker) [homeassistant.components.stream.stream.camera.trg_republike] Error from stream worker: Stream ended; no additional packets
2022-02-16 15:31:43 ERROR (stream_worker) [homeassistant.components.stream.stream.camera.despota_stefana] Error from stream worker: Stream ended; no additional packets
2022-02-16 15:31:45 ERROR (stream_worker) [homeassistant.components.stream.stream.camera.takovska] Error from stream worker: Stream ended; no additional packets
2022-02-16 15:31:46 ERROR (stream_worker) [homeassistant.components.stream.stream.camera.most_gazela] Error from stream worker: Stream ended; no additional packets
2022-02-16 15:31:50 ERROR (stream_worker) [homeassistant.components.stream.stream.camera.bogoslovija] Error from stream worker: Stream ended; no additional packets
2022-02-16 15:31:55 WARNING (stream_worker) [libav.https] HTTP error 404 Not Found
2022-02-16 15:31:55 WARNING (stream_worker) [libav.hls] keepalive request failed for 'https://streamer.devnet.rs/hls/trgrepublike.m3u8' with error: 'Server returned 404 Not Found' when parsing playlist
2022-02-16 15:31:55 WARNING (stream_worker) [libav.https] HTTP error 404 Not Found
2022-02-16 15:31:55 WARNING (stream_worker) [libav.hls] Failed to reload playlist 0
2022-02-16 15:31:55 ERROR (stream_worker) [homeassistant.components.stream.stream.camera.trg_republike] Error from stream worker: Stream ended; no additional packets
2022-02-16 15:32:03 WARNING (stream_worker) [libav.https] HTTP error 404 Not Found
2022-02-16 15:32:03 ERROR (stream_worker) [homeassistant.components.stream.stream.camera.despota_stefana] Error from stream worker: Error opening stream (HTTP_NOT_FOUND, Server returned 404 Not Found) https://streamer.devnet.rs/hls/despotastefana.m3u8
2022-02-16 15:32:05 WARNING (stream_worker) [libav.hls] Cannot get correct #EXTINF value of segment https://streamer.devnet.rs/hls/takovska-128982.ts, set to default value to 1ms.
2022-02-16 15:32:06 WARNING (stream_worker) [libav.hls] Stream #0: not enough frames to estimate rate; consider increasing probesize
2022-02-16 15:32:07 WARNING (stream_worker) [libav.hls] Cannot get correct #EXTINF value of segment https://streamer.devnet.rs/hls/gazela-129049.ts, set to default value to 1ms.
2022-02-16 15:32:08 WARNING (stream_worker) [libav.hls] Stream #0: not enough frames to estimate rate; consider increasing probesize
2022-02-16 15:32:10 WARNING (stream_worker) [libav.hls] Cannot get correct #EXTINF value of segment https://streamer.devnet.rs/hls/bogoslovija-129747.ts, set to default value to 1ms.
2022-02-16 15:32:11 WARNING (stream_worker) [libav.hls] Stream #0: not enough frames to estimate rate; consider increasing probesize
2022-02-16 15:32:15 WARNING (stream_worker) [libav.hls] Cannot get correct #EXTINF value of segment https://streamer.devnet.rs/hls/trgrepublike-128926.ts, set to default value to 1ms.
2022-02-16 15:32:15 WARNING (stream_worker) [libav.hls] Cannot get correct #EXTINF value of segment https://streamer.devnet.rs/hls/takovska-128982.ts, set to default value to 1ms.
2022-02-16 15:32:17 WARNING (stream_worker) [libav.hls] Cannot get correct #EXTINF value of segment https://streamer.devnet.rs/hls/gazela-129049.ts, set to default value to 1ms.
2022-02-16 15:32:21 WARNING (stream_worker) [libav.hls] Cannot get correct #EXTINF value of segment https://streamer.devnet.rs/hls/bogoslovija-129747.ts, set to default value to 1ms.
2022-02-16 15:32:25 WARNING (stream_worker) [libav.hls] Cannot get correct #EXTINF value of segment https://streamer.devnet.rs/hls/trgrepublike-128926.ts, set to default value to 1ms.
2022-02-16 15:32:26 WARNING (stream_worker) [libav.hls] Cannot get correct #EXTINF value of segment https://streamer.devnet.rs/hls/takovska-128982.ts, set to default value to 1ms.
2022-02-16 15:32:27 WARNING (stream_worker) [libav.hls] Cannot get correct #EXTINF value of segment https://streamer.devnet.rs/hls/gazela-129049.ts, set to default value to 1ms.
2022-02-16 15:32:31 WARNING (stream_worker) [libav.hls] Cannot get correct #EXTINF value of segment https://streamer.devnet.rs/hls/bogoslovija-129747.ts, set to default value to 1ms.
2022-02-16 15:32:32 ERROR (stream_worker) [homeassistant.components.stream.stream.camera.autokomanda] Error from stream worker: Stream ended; no additional packets
2022-02-16 15:32:36 WARNING (stream_worker) [libav.hls] Cannot get correct #EXTINF value of segment https://streamer.devnet.rs/hls/trgrepublike-128926.ts, set to default value to 1ms.
2022-02-16 15:32:36 WARNING (stream_worker) [libav.hls] Cannot get correct #EXTINF value of segment https://streamer.devnet.rs/hls/takovska-128982.ts, set to default value to 1ms.
2022-02-16 15:32:37 WARNING (stream_worker) [libav.hls] Cannot get correct #EXTINF value of segment https://streamer.devnet.rs/hls/gazela-129049.ts, set to default value to 1ms.
2022-02-16 15:32:41 WARNING (stream_worker) [libav.hls] Cannot get correct #EXTINF value of segment https://streamer.devnet.rs/hls/bogoslovija-129747.ts, set to default value to 1ms.
2022-02-16 15:32:46 WARNING (stream_worker) [libav.hls] Cannot get correct #EXTINF value of segment https://streamer.devnet.rs/hls/trgrepublike-128926.ts, set to default value to 1ms.
2022-02-16 15:32:46 WARNING (stream_worker) [libav.hls] Cannot get correct #EXTINF value of segment https://streamer.devnet.rs/hls/takovska-128982.ts, set to default value to 1ms.
2022-02-16 15:32:47 WARNING (stream_worker) [libav.hls] Cannot get correct #EXTINF value of segment https://streamer.devnet.rs/hls/gazela-129049.ts, set to default value to 1ms.
2022-02-16 15:32:51 WARNING (stream_worker) [libav.hls] Cannot get correct #EXTINF value of segment https://streamer.devnet.rs/hls/bogoslovija-129747.ts, set to default value to 1ms.
2022-02-16 15:32:56 WARNING (stream_worker) [libav.hls] Cannot get correct #EXTINF value of segment https://streamer.devnet.rs/hls/trgrepublike-128926.ts, set to default value to 1ms.
2022-02-16 15:32:56 WARNING (stream_worker) [libav.hls] Cannot get correct #EXTINF value of segment https://streamer.devnet.rs/hls/takovska-128982.ts, set to default value to 1ms.
2022-02-16 15:32:57 WARNING (stream_worker) [libav.hls] Cannot get correct #EXTINF value of segment https://streamer.devnet.rs/hls/gazela-129049.ts, set to default value to 1ms.
2022-02-16 15:33:01 WARNING (stream_worker) [libav.hls] Cannot get correct #EXTINF value of segment https://streamer.devnet.rs/hls/bogoslovija-129747.ts, set to default value to 1ms.
2022-02-16 15:33:06 WARNING (stream_worker) [libav.hls] Cannot get correct #EXTINF value of segment https://streamer.devnet.rs/hls/trgrepublike-128926.ts, set to default value to 1ms.
2022-02-16 15:33:06 WARNING (stream_worker) [libav.hls] Cannot get correct #EXTINF value of segment https://streamer.devnet.rs/hls/takovska-128982.ts, set to default value to 1ms.
2022-02-16 15:33:07 WARNING (stream_worker) [libav.hls] Cannot get correct #EXTINF value of segment https://streamer.devnet.rs/hls/gazela-129049.ts, set to default value to 1ms.
2022-02-16 15:33:11 WARNING (stream_worker) [libav.hls] Cannot get correct #EXTINF value of segment https://streamer.devnet.rs/hls/bogoslovija-129747.ts, set to default value to 1ms.
2022-02-16 15:33:16 WARNING (stream_worker) [libav.hls] Cannot get correct #EXTINF value of segment https://streamer.devnet.rs/hls/trgrepublike-128926.ts, set to default value to 1ms.
2022-02-16 15:33:16 WARNING (stream_worker) [libav.hls] Cannot get correct #EXTINF value of segment https://streamer.devnet.rs/hls/takovska-128982.ts, set to default value to 1ms.
2022-02-16 15:33:17 WARNING (stream_worker) [libav.hls] Cannot get correct #EXTINF value of segment https://streamer.devnet.rs/hls/gazela-129049.ts, set to default value to 1ms.
2022-02-16 15:33:21 WARNING (stream_worker) [libav.hls] Cannot get correct #EXTINF value of segment https://streamer.devnet.rs/hls/bogoslovija-129747.ts, set to default value to 1ms.
2022-02-16 15:33:26 WARNING (stream_worker) [libav.hls] Cannot get correct #EXTINF value of segment https://streamer.devnet.rs/hls/trgrepublike-128926.ts, set to default value to 1ms.
2022-02-16 15:33:26 WARNING (stream_worker) [libav.hls] Cannot get correct #EXTINF value of segment https://streamer.devnet.rs/hls/takovska-128982.ts, set to default value to 1ms.
2022-02-16 15:33:27 WARNING (stream_worker) [libav.hls] Cannot get correct #EXTINF value of segment https://streamer.devnet.rs/hls/gazela-129049.ts, set to default value to 1ms.
2022-02-16 15:33:31 WARNING (stream_worker) [libav.hls] Cannot get correct #EXTINF value of segment https://streamer.devnet.rs/hls/bogoslovija-129747.ts, set to default value to 1ms.
2022-02-16 15:33:34 ERROR (SyncWorker_13) [spotipy.client] HTTP Error for GET to https://api.spotify.com/v1/me/player/devices with Params: {} returned 401 due to The access token expired
2022-02-16 15:33:34 ERROR (MainThread) [homeassistant.components.spotify] Error fetching Stefan Devices data: 
2022-02-16 15:33:36 WARNING (stream_worker) [libav.hls] Cannot get correct #EXTINF value of segment https://streamer.devnet.rs/hls/trgrepublike-128926.ts, set to default value to 1ms.
2022-02-16 15:33:36 WARNING (stream_worker) [libav.hls] Cannot get correct #EXTINF value of segment https://streamer.devnet.rs/hls/takovska-128982.ts, set to default value to 1ms.
2022-02-16 15:33:38 WARNING (stream_worker) [libav.hls] Cannot get correct #EXTINF value of segment https://streamer.devnet.rs/hls/gazela-129049.ts, set to default value to 1ms.
2022-02-16 15:33:41 WARNING (stream_worker) [libav.hls] Cannot get correct #EXTINF value of segment https://streamer.devnet.rs/hls/bogoslovija-129747.ts, set to default value to 1ms.
2022-02-16 15:33:43 ERROR (stream_worker) [homeassistant.components.stream.stream.camera.autokomanda] Error from stream worker: Stream ended; no additional packets
2022-02-16 15:33:46 WARNING (stream_worker) [libav.hls] Cannot get correct #EXTINF value of segment https://streamer.devnet.rs/hls/trgrepublike-128926.ts, set to default value to 1ms.
2022-02-16 15:33:46 WARNING (stream_worker) [libav.hls] Cannot get correct #EXTINF value of segment https://streamer.devnet.rs/hls/takovska-128982.ts, set to default value to 1ms.
2022-02-16 15:33:48 WARNING (stream_worker) [libav.hls] Cannot get correct #EXTINF value of segment https://streamer.devnet.rs/hls/gazela-129049.ts, set to default value to 1ms.
2022-02-16 15:33:51 WARNING (stream_worker) [libav.hls] Cannot get correct #EXTINF value of segment https://streamer.devnet.rs/hls/bogoslovija-129747.ts, set to default value to 1ms.
2022-02-16 15:33:56 WARNING (stream_worker) [libav.hls] Cannot get correct #EXTINF value of segment https://streamer.devnet.rs/hls/trgrepublike-128926.ts, set to default value to 1ms.
2022-02-16 15:33:56 WARNING (stream_worker) [libav.hls] Cannot get correct #EXTINF value of segment https://streamer.devnet.rs/hls/takovska-128982.ts, set to default value to 1ms.
2022-02-16 15:33:58 WARNING (stream_worker) [libav.hls] Cannot get correct #EXTINF value of segment https://streamer.devnet.rs/hls/gazela-129049.ts, set to default value to 1ms.
2022-02-16 15:34:01 WARNING (stream_worker) [libav.hls] Cannot get correct #EXTINF value of segment https://streamer.devnet.rs/hls/bogoslovija-129747.ts, set to default value to 1ms.
2022-02-16 15:34:03 WARNING (stream_worker) [libav.https] HTTP error 404 Not Found
2022-02-16 15:34:03 ERROR (stream_worker) [homeassistant.components.stream.stream.camera.autokomanda] Error from stream worker: Error opening stream (HTTP_NOT_FOUND, Server returned 404 Not Found) https://streamer.devnet.rs/hls/autokomanda.m3u8
2022-02-16 15:34:06 WARNING (stream_worker) [libav.hls] Cannot get correct #EXTINF value of segment https://streamer.devnet.rs/hls/trgrepublike-128926.ts, set to default value to 1ms.
2022-02-16 15:34:06 WARNING (stream_worker) [libav.hls] Cannot get correct #EXTINF value of segment https://streamer.devnet.rs/hls/takovska-128982.ts, set to default value to 1ms.
2022-02-16 15:34:08 WARNING (stream_worker) [libav.hls] Cannot get correct #EXTINF value of segment https://streamer.devnet.rs/hls/gazela-129049.ts, set to default value to 1ms.
2022-02-16 15:34:11 WARNING (stream_worker) [libav.hls] Cannot get correct #EXTINF value of segment https://streamer.devnet.rs/hls/bogoslovija-129747.ts, set to default value to 1ms.
2022-02-16 15:34:17 WARNING (stream_worker) [libav.hls] Cannot get correct #EXTINF value of segment https://streamer.devnet.rs/hls/trgrepublike-128926.ts, set to default value to 1ms.
2022-02-16 15:34:17 WARNING (stream_worker) [libav.hls] Cannot get correct #EXTINF value of segment https://streamer.devnet.rs/hls/takovska-128982.ts, set to default value to 1ms.
2022-02-16 15:34:18 WARNING (stream_worker) [libav.hls] Cannot get correct #EXTINF value of segment https://streamer.devnet.rs/hls/gazela-129049.ts, set to default value to 1ms.
2022-02-16 15:34:21 WARNING (stream_worker) [libav.hls] Cannot get correct #EXTINF value of segment https://streamer.devnet.rs/hls/bogoslovija-129747.ts, set to default value to 1ms.
2022-02-16 15:34:27 WARNING (stream_worker) [libav.hls] Cannot get correct #EXTINF value of segment https://streamer.devnet.rs/hls/trgrepublike-128926.ts, set to default value to 1ms.
2022-02-16 15:34:27 WARNING (stream_worker) [libav.hls] Cannot get correct #EXTINF value of segment https://streamer.devnet.rs/hls/takovska-128982.ts, set to default value to 1ms.
2022-02-16 15:34:28 WARNING (stream_worker) [libav.hls] Cannot get correct #EXTINF value of segment https://streamer.devnet.rs/hls/gazela-129049.ts, set to default value to 1ms.
2022-02-16 15:34:31 WARNING (stream_worker) [libav.hls] Cannot get correct #EXTINF value of segment https://streamer.devnet.rs/hls/bogoslovija-129747.ts, set to default value to 1ms.
2022-02-16 15:34:34 WARNING (stream_worker) [libav.hls] Cannot get correct #EXTINF value of segment https://streamer.devnet.rs/hls/autokomanda-129962.ts, set to default value to 1ms.
2022-02-16 15:34:37 WARNING (stream_worker) [libav.hls] Cannot get correct #EXTINF value of segment https://streamer.devnet.rs/hls/trgrepublike-128926.ts, set to default value to 1ms.
2022-02-16 15:34:37 WARNING (stream_worker) [libav.hls] Cannot get correct #EXTINF value of segment https://streamer.devnet.rs/hls/takovska-128982.ts, set to default value to 1ms.
2022-02-16 15:34:38 WARNING (stream_worker) [libav.hls] Cannot get correct #EXTINF value of segment https://streamer.devnet.rs/hls/gazela-129049.ts, set to default value to 1ms.
2022-02-16 15:34:41 WARNING (stream_worker) [libav.hls] Cannot get correct #EXTINF value of segment https://streamer.devnet.rs/hls/bogoslovija-129747.ts, set to default value to 1ms.
2022-02-16 15:34:44 WARNING (MainThread) [homeassistant.helpers.service] Unable to find referenced entities scene.warning_lights
2022-02-16 15:34:44 WARNING (MainThread) [homeassistant.helpers.service] Unable to find referenced entities scene.all_lights
2022-02-16 15:34:44 WARNING (stream_worker) [libav.hls] Cannot get correct #EXTINF value of segment https://streamer.devnet.rs/hls/autokomanda-129962.ts, set to default value to 1ms.
2022-02-16 15:34:47 WARNING (stream_worker) [libav.hls] Cannot get correct #EXTINF value of segment https://streamer.devnet.rs/hls/trgrepublike-128926.ts, set to default value to 1ms.
2022-02-16 15:34:47 WARNING (stream_worker) [libav.hls] Cannot get correct #EXTINF value of segment https://streamer.devnet.rs/hls/takovska-128982.ts, set to default value to 1ms.
2022-02-16 15:34:48 WARNING (stream_worker) [libav.hls] Cannot get correct #EXTINF value of segment https://streamer.devnet.rs/hls/gazela-129049.ts, set to default value to 1ms.
2022-02-16 15:34:51 WARNING (stream_worker) [libav.hls] Cannot get correct #EXTINF value of segment https://streamer.devnet.rs/hls/bogoslovija-129747.ts, set to default value to 1ms.
2022-02-16 15:34:54 WARNING (stream_worker) [libav.hls] Cannot get correct #EXTINF value of segment https://streamer.devnet.rs/hls/autokomanda-129962.ts, set to default value to 1ms.
2022-02-16 15:34:57 WARNING (stream_worker) [libav.hls] Cannot get correct #EXTINF value of segment https://streamer.devnet.rs/hls/trgrepublike-128926.ts, set to default value to 1ms.
2022-02-16 15:34:57 WARNING (stream_worker) [libav.hls] Cannot get correct #EXTINF value of segment https://streamer.devnet.rs/hls/takovska-128982.ts, set to default value to 1ms.
2022-02-16 15:34:58 WARNING (stream_worker) [libav.hls] Cannot get correct #EXTINF value of segment https://streamer.devnet.rs/hls/gazela-129049.ts, set to default value to 1ms.
2022-02-16 15:35:01 WARNING (stream_worker) [libav.hls] Cannot get correct #EXTINF value of segment https://streamer.devnet.rs/hls/bogoslovija-129747.ts, set to default value to 1ms.
2022-02-16 15:35:04 WARNING (stream_worker) [libav.hls] Cannot get correct #EXTINF value of segment https://streamer.devnet.rs/hls/autokomanda-129962.ts, set to default value to 1ms.
2022-02-16 15:35:14 WARNING (stream_worker) [libav.hls] Cannot get correct #EXTINF value of segment https://streamer.devnet.rs/hls/autokomanda-129962.ts, set to default value to 1ms.
2022-02-16 15:35:24 WARNING (stream_worker) [libav.hls] Cannot get correct #EXTINF value of segment https://streamer.devnet.rs/hls/autokomanda-129962.ts, set to default value to 1ms.
2022-02-16 15:35:34 WARNING (stream_worker) [libav.hls] Cannot get correct #EXTINF value of segment https://streamer.devnet.rs/hls/autokomanda-129962.ts, set to default value to 1ms.
2022-02-16 15:35:44 WARNING (stream_worker) [libav.hls] Cannot get correct #EXTINF value of segment https://streamer.devnet.rs/hls/autokomanda-129962.ts, set to default value to 1ms.
2022-02-16 15:35:54 WARNING (stream_worker) [libav.hls] Cannot get correct #EXTINF value of segment https://streamer.devnet.rs/hls/autokomanda-129962.ts, set to default value to 1ms.
2022-02-16 15:36:05 WARNING (stream_worker) [libav.hls] Cannot get correct #EXTINF value of segment https://streamer.devnet.rs/hls/autokomanda-129962.ts, set to default value to 1ms.
2022-02-16 15:36:15 WARNING (stream_worker) [libav.hls] Cannot get correct #EXTINF value of segment https://streamer.devnet.rs/hls/autokomanda-129962.ts, set to default value to 1ms.
2022-02-16 15:36:25 WARNING (stream_worker) [libav.hls] Cannot get correct #EXTINF value of segment https://streamer.devnet.rs/hls/autokomanda-129962.ts, set to default value to 1ms.
2022-02-16 15:36:35 WARNING (stream_worker) [libav.hls] Cannot get correct #EXTINF value of segment https://streamer.devnet.rs/hls/autokomanda-129962.ts, set to default value to 1ms.
2022-02-16 15:36:45 WARNING (stream_worker) [libav.hls] Cannot get correct #EXTINF value of segment https://streamer.devnet.rs/hls/autokomanda-129962.ts, set to default value to 1ms.
2022-02-16 15:36:55 WARNING (stream_worker) [libav.hls] Cannot get correct #EXTINF value of segment https://streamer.devnet.rs/hls/autokomanda-129962.ts, set to default value to 1ms.
2022-02-16 15:37:05 WARNING (stream_worker) [libav.hls] Cannot get correct #EXTINF value of segment https://streamer.devnet.rs/hls/autokomanda-129962.ts, set to default value to 1ms.
2022-02-16 15:38:34 ERROR (SyncWorker_7) [spotipy.client] HTTP Error for GET to https://api.spotify.com/v1/me/player/devices with Params: {} returned 401 due to The access token expired
2022-02-16 15:38:58 INFO (MainThread) [backoff] Backing off fetch_events(...) for 0.2s (pyoverkiz.exceptions.InvalidEventListenerIdException: Invalid event listener id : 02c1efb6-98e4-e192-403a-40597745aa20)
2022-02-16 15:40:22 ERROR (stream_worker) [homeassistant.components.stream.stream.camera.zeleznicka] Error from stream worker: Stream ended; no additional packets
2022-02-16 15:40:22 ERROR (stream_worker) [homeassistant.components.stream.stream.camera.genex] Error from stream worker: Stream ended; no additional packets
2022-02-16 15:41:28 WARNING (stream_worker) [libav.https] HTTP error 404 Not Found
2022-02-16 15:41:28 WARNING (stream_worker) [libav.hls] keepalive request failed for 'https://streamer.devnet.rs/hls/zeleznicka.m3u8' with error: 'Server returned 404 Not Found' when parsing playlist
2022-02-16 15:41:28 WARNING (stream_worker) [libav.https] HTTP error 404 Not Found
2022-02-16 15:41:28 WARNING (stream_worker) [libav.hls] Failed to reload playlist 0
2022-02-16 15:41:28 ERROR (stream_worker) [homeassistant.components.stream.stream.camera.zeleznicka] Error from stream worker: Stream ended; no additional packets
2022-02-16 15:41:30 WARNING (stream_worker) [libav.https] HTTP error 404 Not Found
2022-02-16 15:41:30 WARNING (stream_worker) [libav.hls] keepalive request failed for 'https://streamer.devnet.rs/hls/genex.m3u8' with error: 'Server returned 404 Not Found' when parsing playlist
2022-02-16 15:41:30 WARNING (stream_worker) [libav.https] HTTP error 404 Not Found
2022-02-16 15:41:30 WARNING (stream_worker) [libav.hls] Failed to reload playlist 0
2022-02-16 15:41:30 ERROR (stream_worker) [homeassistant.components.stream.stream.camera.genex] Error from stream worker: Stream ended; no additional packets
2022-02-16 15:41:49 WARNING (stream_worker) [libav.https] HTTP error 404 Not Found
2022-02-16 15:41:49 ERROR (stream_worker) [homeassistant.components.stream.stream.camera.zeleznicka] Error from stream worker: Error opening stream (HTTP_NOT_FOUND, Server returned 404 Not Found) https://streamer.devnet.rs/hls/zeleznicka.m3u8
2022-02-16 15:41:50 WARNING (stream_worker) [libav.https] HTTP error 404 Not Found
2022-02-16 15:41:50 ERROR (stream_worker) [homeassistant.components.stream.stream.camera.genex] Error from stream worker: Error opening stream (HTTP_NOT_FOUND, Server returned 404 Not Found) https://streamer.devnet.rs/hls/genex.m3u8
2022-02-16 15:41:51 WARNING (stream_worker) [libav.hls] keepalive request failed for 'https://streamer.devnet.rs/hls/vuk.m3u8' with error: 'I/O error' when parsing playlist
2022-02-16 15:42:21 WARNING (stream_worker) [libav.hls] Cannot get correct #EXTINF value of segment https://streamer.devnet.rs/hls/genex-129068.ts, set to default value to 1ms.
2022-02-16 15:42:21 ERROR (stream_worker) [homeassistant.components.stream.stream.camera.vukov_spomenik] Error from stream worker: Stream ended; no additional packets
2022-02-16 15:42:31 ERROR (stream_worker) [homeassistant.components.stream.stream.camera.brankov_most] Error from stream worker: Stream ended; no additional packets
2022-02-16 15:42:31 WARNING (stream_worker) [libav.hls] Cannot get correct #EXTINF value of segment https://streamer.devnet.rs/hls/genex-129068.ts, set to default value to 1ms.
2022-02-16 15:42:41 WARNING (stream_worker) [libav.hls] Cannot get correct #EXTINF value of segment https://streamer.devnet.rs/hls/genex-129068.ts, set to default value to 1ms.
2022-02-16 15:42:51 WARNING (stream_worker) [libav.hls] Cannot get correct #EXTINF value of segment https://streamer.devnet.rs/hls/genex-129068.ts, set to default value to 1ms.
2022-02-16 15:43:01 WARNING (stream_worker) [libav.hls] Cannot get correct #EXTINF value of segment https://streamer.devnet.rs/hls/genex-129068.ts, set to default value to 1ms.
2022-02-16 15:43:11 WARNING (stream_worker) [libav.hls] Cannot get correct #EXTINF value of segment https://streamer.devnet.rs/hls/genex-129068.ts, set to default value to 1ms.
2022-02-16 15:43:22 WARNING (stream_worker) [libav.hls] Cannot get correct #EXTINF value of segment https://streamer.devnet.rs/hls/genex-129068.ts, set to default value to 1ms.
2022-02-16 15:43:27 WARNING (stream_worker) [libav.https] HTTP error 404 Not Found
2022-02-16 15:43:27 WARNING (stream_worker) [libav.hls] keepalive request failed for 'https://streamer.devnet.rs/hls/vuk.m3u8' with error: 'Server returned 404 Not Found' when parsing playlist
2022-02-16 15:43:27 WARNING (stream_worker) [libav.https] HTTP error 404 Not Found
2022-02-16 15:43:27 WARNING (stream_worker) [libav.hls] Failed to reload playlist 0
2022-02-16 15:43:27 ERROR (stream_worker) [homeassistant.components.stream.stream.camera.vukov_spomenik] Error from stream worker: Stream ended; no additional packets
2022-02-16 15:43:32 WARNING (stream_worker) [libav.hls] Cannot get correct #EXTINF value of segment https://streamer.devnet.rs/hls/genex-129068.ts, set to default value to 1ms.
2022-02-16 15:43:34 ERROR (SyncWorker_9) [spotipy.client] HTTP Error for GET to https://api.spotify.com/v1/me/player/devices with Params: {} returned 401 due to The access token expired
2022-02-16 15:43:42 WARNING (stream_worker) [libav.hls] Cannot get correct #EXTINF value of segment https://streamer.devnet.rs/hls/genex-129068.ts, set to default value to 1ms.
2022-02-16 15:43:42 ERROR (stream_worker) [homeassistant.components.stream.stream.camera.brankov_most] Error from stream worker: Stream ended; no additional packets
2022-02-16 15:43:48 WARNING (stream_worker) [libav.https] HTTP error 404 Not Found
2022-02-16 15:43:48 ERROR (stream_worker) [homeassistant.components.stream.stream.camera.vukov_spomenik] Error from stream worker: Error opening stream (HTTP_NOT_FOUND, Server returned 404 Not Found) https://streamer.devnet.rs/hls/vuk.m3u8
2022-02-16 15:43:52 WARNING (stream_worker) [libav.hls] Cannot get correct #EXTINF value of segment https://streamer.devnet.rs/hls/genex-129068.ts, set to default value to 1ms.
2022-02-16 15:44:02 WARNING (stream_worker) [libav.hls] Cannot get correct #EXTINF value of segment https://streamer.devnet.rs/hls/genex-129068.ts, set to default value to 1ms.
2022-02-16 15:44:02 WARNING (stream_worker) [libav.hls] Cannot get correct #EXTINF value of segment https://streamer.devnet.rs/hls/brankov-128899.ts, set to default value to 1ms.
2022-02-16 15:44:03 WARNING (stream_worker) [libav.https] HTTP error 404 Not Found
2022-02-16 15:44:03 WARNING (stream_worker) [libav.hls] Failed to open segment 128897 of playlist 0
2022-02-16 15:44:03 WARNING (stream_worker) [libav.hls] Cannot get correct #EXTINF value of segment https://streamer.devnet.rs/hls/brankov-128899.ts, set to default value to 1ms.
2022-02-16 15:44:03 WARNING (stream_worker) [libav.https] HTTP error 404 Not Found
2022-02-16 15:44:03 WARNING (stream_worker) [libav.hls] Failed to open segment 128898 of playlist 0
2022-02-16 15:44:04 WARNING (stream_worker) [libav.hls] Stream #0: not enough frames to estimate rate; consider increasing probesize
2022-02-16 15:44:12 WARNING (stream_worker) [libav.hls] Cannot get correct #EXTINF value of segment https://streamer.devnet.rs/hls/genex-129068.ts, set to default value to 1ms.
2022-02-16 15:44:13 WARNING (stream_worker) [libav.hls] Cannot get correct #EXTINF value of segment https://streamer.devnet.rs/hls/brankov-128899.ts, set to default value to 1ms.
2022-02-16 15:44:22 WARNING (stream_worker) [libav.hls] Cannot get correct #EXTINF value of segment https://streamer.devnet.rs/hls/genex-129068.ts, set to default value to 1ms.
2022-02-16 15:44:23 WARNING (stream_worker) [libav.hls] Cannot get correct #EXTINF value of segment https://streamer.devnet.rs/hls/brankov-128899.ts, set to default value to 1ms.
2022-02-16 15:44:32 WARNING (stream_worker) [libav.hls] Cannot get correct #EXTINF value of segment https://streamer.devnet.rs/hls/genex-129068.ts, set to default value to 1ms.
2022-02-16 15:44:33 WARNING (stream_worker) [libav.hls] Cannot get correct #EXTINF value of segment https://streamer.devnet.rs/hls/brankov-128899.ts, set to default value to 1ms.
2022-02-16 15:44:42 WARNING (stream_worker) [libav.hls] Cannot get correct #EXTINF value of segment https://streamer.devnet.rs/hls/genex-129068.ts, set to default value to 1ms.
2022-02-16 15:44:43 WARNING (stream_worker) [libav.hls] Cannot get correct #EXTINF value of segment https://streamer.devnet.rs/hls/brankov-128899.ts, set to default value to 1ms.
2022-02-16 15:44:52 WARNING (stream_worker) [libav.hls] Cannot get correct #EXTINF value of segment https://streamer.devnet.rs/hls/genex-129068.ts, set to default value to 1ms.
2022-02-16 15:44:53 WARNING (stream_worker) [libav.hls] Cannot get correct #EXTINF value of segment https://streamer.devnet.rs/hls/brankov-128899.ts, set to default value to 1ms.
2022-02-16 15:45:02 WARNING (stream_worker) [libav.hls] Cannot get correct #EXTINF value of segment https://streamer.devnet.rs/hls/genex-129068.ts, set to default value to 1ms.
2022-02-16 15:45:04 WARNING (stream_worker) [libav.hls] Cannot get correct #EXTINF value of segment https://streamer.devnet.rs/hls/brankov-128899.ts, set to default value to 1ms.
2022-02-16 15:45:14 WARNING (stream_worker) [libav.hls] Cannot get correct #EXTINF value of segment https://streamer.devnet.rs/hls/brankov-128899.ts, set to default value to 1ms.
2022-02-16 15:45:24 WARNING (stream_worker) [libav.hls] Cannot get correct #EXTINF value of segment https://streamer.devnet.rs/hls/brankov-128899.ts, set to default value to 1ms.
2022-02-16 15:45:34 WARNING (stream_worker) [libav.hls] Cannot get correct #EXTINF value of segment https://streamer.devnet.rs/hls/brankov-128899.ts, set to default value to 1ms.
2022-02-16 15:45:44 WARNING (stream_worker) [libav.hls] Cannot get correct #EXTINF value of segment https://streamer.devnet.rs/hls/brankov-128899.ts, set to default value to 1ms.
2022-02-16 15:45:54 WARNING (stream_worker) [libav.hls] Cannot get correct #EXTINF value of segment https://streamer.devnet.rs/hls/brankov-128899.ts, set to default value to 1ms.
2022-02-16 15:46:04 WARNING (stream_worker) [libav.hls] Cannot get correct #EXTINF value of segment https://streamer.devnet.rs/hls/brankov-128899.ts, set to default value to 1ms.
2022-02-16 15:46:14 WARNING (stream_worker) [libav.hls] Cannot get correct #EXTINF value of segment https://streamer.devnet.rs/hls/brankov-128899.ts, set to default value to 1ms.
2022-02-16 15:46:24 WARNING (stream_worker) [libav.hls] Cannot get correct #EXTINF value of segment https://streamer.devnet.rs/hls/brankov-128899.ts, set to default value to 1ms.
2022-02-16 15:46:34 WARNING (stream_worker) [libav.hls] Cannot get correct #EXTINF value of segment https://streamer.devnet.rs/hls/brankov-128899.ts, set to default value to 1ms.
2022-02-16 15:46:44 WARNING (stream_worker) [libav.hls] Cannot get correct #EXTINF value of segment https://streamer.devnet.rs/hls/brankov-128899.ts, set to default value to 1ms.
2022-02-16 15:48:34 ERROR (SyncWorker_6) [spotipy.client] HTTP Error for GET to https://api.spotify.com/v1/me/player/devices with Params: {} returned 401 due to The access token expired
2022-02-16 15:49:57 WARNING (Thread-534) [custom_components.aquaariston.aristonaqua] <custom_components.aquaariston.aristonaqua.AquaAristonHandler object at 0x149dcf2f60a0> _get_cleanse Problem reading data
2022-02-16 15:49:57 WARNING (Thread-534) [custom_components.aquaariston.aristonaqua] ariston action nok for _get_cleanse: Request _get_cleanse has failed with an exception
2022-02-16 15:53:34 ERROR (SyncWorker_13) [spotipy.client] HTTP Error for GET to https://api.spotify.com/v1/me/player/devices with Params: {} returned 401 due to The access token expired
2022-02-16 15:58:34 ERROR (SyncWorker_12) [spotipy.client] HTTP Error for GET to https://api.spotify.com/v1/me/player/devices with Params: {} returned 401 due to The access token expired
2022-02-16 16:03:34 ERROR (SyncWorker_12) [spotipy.client] HTTP Error for GET to https://api.spotify.com/v1/me/player/devices with Params: {} returned 401 due to The access token expired
2022-02-16 16:08:34 ERROR (SyncWorker_9) [spotipy.client] HTTP Error for GET to https://api.spotify.com/v1/me/player/devices with Params: {} returned 401 due to The access token expired
2022-02-16 16:09:17 WARNING (MainThread) [homeassistant.helpers.service] Unable to find referenced entities switch.terace_wall_light
2022-02-16 16:11:41 WARNING (MainThread) [homeassistant.components.automation.kitchen_extraction_fan_toggle_by_kitchen_stove] Kitchen extraction fan toggle by kitchen stove: Already running
2022-02-16 16:11:43 WARNING (MainThread) [homeassistant.components.automation.kitchen_extraction_fan_toggle_by_kitchen_stove] Kitchen extraction fan toggle by kitchen stove: Already running
2022-02-16 16:12:49 ERROR (MainThread) [homeassistant] Error doing job: Task exception was never retrieved
Traceback (most recent call last):
  File "/usr/src/homeassistant/homeassistant/core.py", line 1584, in async_call
    processed_data: dict[str, Any] = handler.schema(service_data)
  File "/usr/local/lib/python3.9/site-packages/voluptuous/validators.py", line 218, in __call__
    return self._exec((Schema(val) for val in self.validators), v)
  File "/usr/local/lib/python3.9/site-packages/voluptuous/validators.py", line 341, in _exec
    raise e if self.msg is None else AllInvalid(self.msg, path=path)
  File "/usr/local/lib/python3.9/site-packages/voluptuous/validators.py", line 337, in _exec
    v = func(v)
  File "/usr/local/lib/python3.9/site-packages/voluptuous/schema_builder.py", line 272, in __call__
    return self._compiled([], data)
  File "/usr/local/lib/python3.9/site-packages/voluptuous/schema_builder.py", line 817, in validate_callable
    return schema(data)
  File "/usr/local/lib/python3.9/site-packages/voluptuous/schema_builder.py", line 272, in __call__
    return self._compiled([], data)
  File "/usr/local/lib/python3.9/site-packages/voluptuous/validators.py", line 215, in _run
    return self._exec(self._compiled, value, path)
  File "/usr/local/lib/python3.9/site-packages/voluptuous/validators.py", line 341, in _exec
    raise e if self.msg is None else AllInvalid(self.msg, path=path)
  File "/usr/local/lib/python3.9/site-packages/voluptuous/validators.py", line 339, in _exec
    v = func(path, v)
  File "/usr/local/lib/python3.9/site-packages/voluptuous/schema_builder.py", line 817, in validate_callable
    return schema(data)
  File "/usr/local/lib/python3.9/site-packages/voluptuous/schema_builder.py", line 272, in __call__
    return self._compiled([], data)
  File "/usr/local/lib/python3.9/site-packages/voluptuous/schema_builder.py", line 594, in validate_dict
    return base_validate(path, iteritems(data), out)
  File "/usr/local/lib/python3.9/site-packages/voluptuous/schema_builder.py", line 432, in validate_mapping
    raise er.MultipleInvalid(errors)
voluptuous.error.MultipleInvalid: value must be at most 100 for dictionary value @ data['brightness_pct']
2022-02-16 16:12:49 ERROR (MainThread) [homeassistant] Error doing job: Task exception was never retrieved
Traceback (most recent call last):
  File "/usr/src/homeassistant/homeassistant/core.py", line 1584, in async_call
    processed_data: dict[str, Any] = handler.schema(service_data)
  File "/usr/local/lib/python3.9/site-packages/voluptuous/validators.py", line 218, in __call__
    return self._exec((Schema(val) for val in self.validators), v)
  File "/usr/local/lib/python3.9/site-packages/voluptuous/validators.py", line 341, in _exec
    raise e if self.msg is None else AllInvalid(self.msg, path=path)
  File "/usr/local/lib/python3.9/site-packages/voluptuous/validators.py", line 337, in _exec
    v = func(v)
  File "/usr/local/lib/python3.9/site-packages/voluptuous/schema_builder.py", line 272, in __call__
    return self._compiled([], data)
  File "/usr/local/lib/python3.9/site-packages/voluptuous/schema_builder.py", line 817, in validate_callable
    return schema(data)
  File "/usr/local/lib/python3.9/site-packages/voluptuous/schema_builder.py", line 272, in __call__
    return self._compiled([], data)
  File "/usr/local/lib/python3.9/site-packages/voluptuous/validators.py", line 215, in _run
    return self._exec(self._compiled, value, path)
  File "/usr/local/lib/python3.9/site-packages/voluptuous/validators.py", line 341, in _exec
    raise e if self.msg is None else AllInvalid(self.msg, path=path)
  File "/usr/local/lib/python3.9/site-packages/voluptuous/validators.py", line 339, in _exec
    v = func(path, v)
  File "/usr/local/lib/python3.9/site-packages/voluptuous/schema_builder.py", line 817, in validate_callable
    return schema(data)
  File "/usr/local/lib/python3.9/site-packages/voluptuous/schema_builder.py", line 272, in __call__
    return self._compiled([], data)
  File "/usr/local/lib/python3.9/site-packages/voluptuous/schema_builder.py", line 594, in validate_dict
    return base_validate(path, iteritems(data), out)
  File "/usr/local/lib/python3.9/site-packages/voluptuous/schema_builder.py", line 432, in validate_mapping
    raise er.MultipleInvalid(errors)
voluptuous.error.MultipleInvalid: value must be at most 100 for dictionary value @ data['brightness_pct']
2022-02-16 16:12:49 ERROR (MainThread) [homeassistant] Error doing job: Task exception was never retrieved
Traceback (most recent call last):
  File "/usr/src/homeassistant/homeassistant/core.py", line 1584, in async_call
    processed_data: dict[str, Any] = handler.schema(service_data)
  File "/usr/local/lib/python3.9/site-packages/voluptuous/validators.py", line 218, in __call__
    return self._exec((Schema(val) for val in self.validators), v)
  File "/usr/local/lib/python3.9/site-packages/voluptuous/validators.py", line 341, in _exec
    raise e if self.msg is None else AllInvalid(self.msg, path=path)
  File "/usr/local/lib/python3.9/site-packages/voluptuous/validators.py", line 337, in _exec
    v = func(v)
  File "/usr/local/lib/python3.9/site-packages/voluptuous/schema_builder.py", line 272, in __call__
    return self._compiled([], data)
  File "/usr/local/lib/python3.9/site-packages/voluptuous/schema_builder.py", line 817, in validate_callable
    return schema(data)
  File "/usr/local/lib/python3.9/site-packages/voluptuous/schema_builder.py", line 272, in __call__
    return self._compiled([], data)
  File "/usr/local/lib/python3.9/site-packages/voluptuous/validators.py", line 215, in _run
    return self._exec(self._compiled, value, path)
  File "/usr/local/lib/python3.9/site-packages/voluptuous/validators.py", line 341, in _exec
    raise e if self.msg is None else AllInvalid(self.msg, path=path)
  File "/usr/local/lib/python3.9/site-packages/voluptuous/validators.py", line 339, in _exec
    v = func(path, v)
  File "/usr/local/lib/python3.9/site-packages/voluptuous/schema_builder.py", line 817, in validate_callable
    return schema(data)
  File "/usr/local/lib/python3.9/site-packages/voluptuous/schema_builder.py", line 272, in __call__
    return self._compiled([], data)
  File "/usr/local/lib/python3.9/site-packages/voluptuous/schema_builder.py", line 594, in validate_dict
    return base_validate(path, iteritems(data), out)
  File "/usr/local/lib/python3.9/site-packages/voluptuous/schema_builder.py", line 432, in validate_mapping
    raise er.MultipleInvalid(errors)
voluptuous.error.MultipleInvalid: value must be at most 100 for dictionary value @ data['brightness_pct']
2022-02-16 16:12:49 ERROR (MainThread) [homeassistant] Error doing job: Task exception was never retrieved
Traceback (most recent call last):
  File "/usr/src/homeassistant/homeassistant/core.py", line 1584, in async_call
    processed_data: dict[str, Any] = handler.schema(service_data)
  File "/usr/local/lib/python3.9/site-packages/voluptuous/validators.py", line 218, in __call__
    return self._exec((Schema(val) for val in self.validators), v)
  File "/usr/local/lib/python3.9/site-packages/voluptuous/validators.py", line 341, in _exec
    raise e if self.msg is None else AllInvalid(self.msg, path=path)
  File "/usr/local/lib/python3.9/site-packages/voluptuous/validators.py", line 337, in _exec
    v = func(v)
  File "/usr/local/lib/python3.9/site-packages/voluptuous/schema_builder.py", line 272, in __call__
    return self._compiled([], data)
  File "/usr/local/lib/python3.9/site-packages/voluptuous/schema_builder.py", line 817, in validate_callable
    return schema(data)
  File "/usr/local/lib/python3.9/site-packages/voluptuous/schema_builder.py", line 272, in __call__
    return self._compiled([], data)
  File "/usr/local/lib/python3.9/site-packages/voluptuous/validators.py", line 215, in _run
    return self._exec(self._compiled, value, path)
  File "/usr/local/lib/python3.9/site-packages/voluptuous/validators.py", line 341, in _exec
    raise e if self.msg is None else AllInvalid(self.msg, path=path)
  File "/usr/local/lib/python3.9/site-packages/voluptuous/validators.py", line 339, in _exec
    v = func(path, v)
  File "/usr/local/lib/python3.9/site-packages/voluptuous/schema_builder.py", line 817, in validate_callable
    return schema(data)
  File "/usr/local/lib/python3.9/site-packages/voluptuous/schema_builder.py", line 272, in __call__
    return self._compiled([], data)
  File "/usr/local/lib/python3.9/site-packages/voluptuous/schema_builder.py", line 594, in validate_dict
    return base_validate(path, iteritems(data), out)
  File "/usr/local/lib/python3.9/site-packages/voluptuous/schema_builder.py", line 432, in validate_mapping
    raise er.MultipleInvalid(errors)
voluptuous.error.MultipleInvalid: value must be at most 100 for dictionary value @ data['brightness_pct']
2022-02-16 16:12:49 ERROR (MainThread) [homeassistant] Error doing job: Task exception was never retrieved
Traceback (most recent call last):
  File "/usr/src/homeassistant/homeassistant/core.py", line 1584, in async_call
    processed_data: dict[str, Any] = handler.schema(service_data)
  File "/usr/local/lib/python3.9/site-packages/voluptuous/validators.py", line 218, in __call__
    return self._exec((Schema(val) for val in self.validators), v)
  File "/usr/local/lib/python3.9/site-packages/voluptuous/validators.py", line 341, in _exec
    raise e if self.msg is None else AllInvalid(self.msg, path=path)
  File "/usr/local/lib/python3.9/site-packages/voluptuous/validators.py", line 337, in _exec
    v = func(v)
  File "/usr/local/lib/python3.9/site-packages/voluptuous/schema_builder.py", line 272, in __call__
    return self._compiled([], data)
  File "/usr/local/lib/python3.9/site-packages/voluptuous/schema_builder.py", line 817, in validate_callable
    return schema(data)
  File "/usr/local/lib/python3.9/site-packages/voluptuous/schema_builder.py", line 272, in __call__
    return self._compiled([], data)
  File "/usr/local/lib/python3.9/site-packages/voluptuous/validators.py", line 215, in _run
    return self._exec(self._compiled, value, path)
  File "/usr/local/lib/python3.9/site-packages/voluptuous/validators.py", line 341, in _exec
    raise e if self.msg is None else AllInvalid(self.msg, path=path)
  File "/usr/local/lib/python3.9/site-packages/voluptuous/validators.py", line 339, in _exec
    v = func(path, v)
  File "/usr/local/lib/python3.9/site-packages/voluptuous/schema_builder.py", line 817, in validate_callable
    return schema(data)
  File "/usr/local/lib/python3.9/site-packages/voluptuous/schema_builder.py", line 272, in __call__
    return self._compiled([], data)
  File "/usr/local/lib/python3.9/site-packages/voluptuous/schema_builder.py", line 594, in validate_dict
    return base_validate(path, iteritems(data), out)
  File "/usr/local/lib/python3.9/site-packages/voluptuous/schema_builder.py", line 432, in validate_mapping
    raise er.MultipleInvalid(errors)
voluptuous.error.MultipleInvalid: value must be at most 100 for dictionary value @ data['brightness_pct']
2022-02-16 16:12:50 ERROR (MainThread) [homeassistant] Error doing job: Task exception was never retrieved
Traceback (most recent call last):
  File "/usr/src/homeassistant/homeassistant/core.py", line 1584, in async_call
    processed_data: dict[str, Any] = handler.schema(service_data)
  File "/usr/local/lib/python3.9/site-packages/voluptuous/validators.py", line 218, in __call__
    return self._exec((Schema(val) for val in self.validators), v)
  File "/usr/local/lib/python3.9/site-packages/voluptuous/validators.py", line 341, in _exec
    raise e if self.msg is None else AllInvalid(self.msg, path=path)
  File "/usr/local/lib/python3.9/site-packages/voluptuous/validators.py", line 337, in _exec
    v = func(v)
  File "/usr/local/lib/python3.9/site-packages/voluptuous/schema_builder.py", line 272, in __call__
    return self._compiled([], data)
  File "/usr/local/lib/python3.9/site-packages/voluptuous/schema_builder.py", line 817, in validate_callable
    return schema(data)
  File "/usr/local/lib/python3.9/site-packages/voluptuous/schema_builder.py", line 272, in __call__
    return self._compiled([], data)
  File "/usr/local/lib/python3.9/site-packages/voluptuous/validators.py", line 215, in _run
    return self._exec(self._compiled, value, path)
  File "/usr/local/lib/python3.9/site-packages/voluptuous/validators.py", line 341, in _exec
    raise e if self.msg is None else AllInvalid(self.msg, path=path)
  File "/usr/local/lib/python3.9/site-packages/voluptuous/validators.py", line 339, in _exec
    v = func(path, v)
  File "/usr/local/lib/python3.9/site-packages/voluptuous/schema_builder.py", line 817, in validate_callable
    return schema(data)
  File "/usr/local/lib/python3.9/site-packages/voluptuous/schema_builder.py", line 272, in __call__
    return self._compiled([], data)
  File "/usr/local/lib/python3.9/site-packages/voluptuous/schema_builder.py", line 594, in validate_dict
    return base_validate(path, iteritems(data), out)
  File "/usr/local/lib/python3.9/site-packages/voluptuous/schema_builder.py", line 432, in validate_mapping
    raise er.MultipleInvalid(errors)
voluptuous.error.MultipleInvalid: value must be at most 100 for dictionary value @ data['brightness_pct']
2022-02-16 16:12:50 ERROR (MainThread) [homeassistant] Error doing job: Task exception was never retrieved
Traceback (most recent call last):
  File "/usr/src/homeassistant/homeassistant/core.py", line 1584, in async_call
    processed_data: dict[str, Any] = handler.schema(service_data)
  File "/usr/local/lib/python3.9/site-packages/voluptuous/validators.py", line 218, in __call__
    return self._exec((Schema(val) for val in self.validators), v)
  File "/usr/local/lib/python3.9/site-packages/voluptuous/validators.py", line 341, in _exec
    raise e if self.msg is None else AllInvalid(self.msg, path=path)
  File "/usr/local/lib/python3.9/site-packages/voluptuous/validators.py", line 337, in _exec
    v = func(v)
  File "/usr/local/lib/python3.9/site-packages/voluptuous/schema_builder.py", line 272, in __call__
    return self._compiled([], data)
  File "/usr/local/lib/python3.9/site-packages/voluptuous/schema_builder.py", line 817, in validate_callable
    return schema(data)
  File "/usr/local/lib/python3.9/site-packages/voluptuous/schema_builder.py", line 272, in __call__
    return self._compiled([], data)
  File "/usr/local/lib/python3.9/site-packages/voluptuous/validators.py", line 215, in _run
    return self._exec(self._compiled, value, path)
  File "/usr/local/lib/python3.9/site-packages/voluptuous/validators.py", line 341, in _exec
    raise e if self.msg is None else AllInvalid(self.msg, path=path)
  File "/usr/local/lib/python3.9/site-packages/voluptuous/validators.py", line 339, in _exec
    v = func(path, v)
  File "/usr/local/lib/python3.9/site-packages/voluptuous/schema_builder.py", line 817, in validate_callable
    return schema(data)
  File "/usr/local/lib/python3.9/site-packages/voluptuous/schema_builder.py", line 272, in __call__
    return self._compiled([], data)
  File "/usr/local/lib/python3.9/site-packages/voluptuous/schema_builder.py", line 594, in validate_dict
    return base_validate(path, iteritems(data), out)
  File "/usr/local/lib/python3.9/site-packages/voluptuous/schema_builder.py", line 432, in validate_mapping
    raise er.MultipleInvalid(errors)
voluptuous.error.MultipleInvalid: value must be at most 100 for dictionary value @ data['brightness_pct']
2022-02-16 16:12:50 ERROR (MainThread) [homeassistant] Error doing job: Task exception was never retrieved
Traceback (most recent call last):
  File "/usr/src/homeassistant/homeassistant/core.py", line 1584, in async_call
    processed_data: dict[str, Any] = handler.schema(service_data)
  File "/usr/local/lib/python3.9/site-packages/voluptuous/validators.py", line 218, in __call__
    return self._exec((Schema(val) for val in self.validators), v)
  File "/usr/local/lib/python3.9/site-packages/voluptuous/validators.py", line 341, in _exec
    raise e if self.msg is None else AllInvalid(self.msg, path=path)
  File "/usr/local/lib/python3.9/site-packages/voluptuous/validators.py", line 337, in _exec
    v = func(v)
  File "/usr/local/lib/python3.9/site-packages/voluptuous/schema_builder.py", line 272, in __call__
    return self._compiled([], data)
  File "/usr/local/lib/python3.9/site-packages/voluptuous/schema_builder.py", line 817, in validate_callable
    return schema(data)
  File "/usr/local/lib/python3.9/site-packages/voluptuous/schema_builder.py", line 272, in __call__
    return self._compiled([], data)
  File "/usr/local/lib/python3.9/site-packages/voluptuous/validators.py", line 215, in _run
    return self._exec(self._compiled, value, path)
  File "/usr/local/lib/python3.9/site-packages/voluptuous/validators.py", line 341, in _exec
    raise e if self.msg is None else AllInvalid(self.msg, path=path)
  File "/usr/local/lib/python3.9/site-packages/voluptuous/validators.py", line 339, in _exec
    v = func(path, v)
  File "/usr/local/lib/python3.9/site-packages/voluptuous/schema_builder.py", line 817, in validate_callable
    return schema(data)
  File "/usr/local/lib/python3.9/site-packages/voluptuous/schema_builder.py", line 272, in __call__
    return self._compiled([], data)
  File "/usr/local/lib/python3.9/site-packages/voluptuous/schema_builder.py", line 594, in validate_dict
    return base_validate(path, iteritems(data), out)
  File "/usr/local/lib/python3.9/site-packages/voluptuous/schema_builder.py", line 432, in validate_mapping
    raise er.MultipleInvalid(errors)
voluptuous.error.MultipleInvalid: value must be at most 100 for dictionary value @ data['brightness_pct']
2022-02-16 16:12:50 ERROR (MainThread) [homeassistant] Error doing job: Task exception was never retrieved
Traceback (most recent call last):
  File "/usr/src/homeassistant/homeassistant/core.py", line 1584, in async_call
    processed_data: dict[str, Any] = handler.schema(service_data)
  File "/usr/local/lib/python3.9/site-packages/voluptuous/validators.py", line 218, in __call__
    return self._exec((Schema(val) for val in self.validators), v)
  File "/usr/local/lib/python3.9/site-packages/voluptuous/validators.py", line 341, in _exec
    raise e if self.msg is None else AllInvalid(self.msg, path=path)
  File "/usr/local/lib/python3.9/site-packages/voluptuous/validators.py", line 337, in _exec
    v = func(v)
  File "/usr/local/lib/python3.9/site-packages/voluptuous/schema_builder.py", line 272, in __call__
    return self._compiled([], data)
  File "/usr/local/lib/python3.9/site-packages/voluptuous/schema_builder.py", line 817, in validate_callable
    return schema(data)
  File "/usr/local/lib/python3.9/site-packages/voluptuous/schema_builder.py", line 272, in __call__
    return self._compiled([], data)
  File "/usr/local/lib/python3.9/site-packages/voluptuous/validators.py", line 215, in _run
    return self._exec(self._compiled, value, path)
  File "/usr/local/lib/python3.9/site-packages/voluptuous/validators.py", line 341, in _exec
    raise e if self.msg is None else AllInvalid(self.msg, path=path)
  File "/usr/local/lib/python3.9/site-packages/voluptuous/validators.py", line 339, in _exec
    v = func(path, v)
  File "/usr/local/lib/python3.9/site-packages/voluptuous/schema_builder.py", line 817, in validate_callable
    return schema(data)
  File "/usr/local/lib/python3.9/site-packages/voluptuous/schema_builder.py", line 272, in __call__
    return self._compiled([], data)
  File "/usr/local/lib/python3.9/site-packages/voluptuous/schema_builder.py", line 594, in validate_dict
    return base_validate(path, iteritems(data), out)
  File "/usr/local/lib/python3.9/site-packages/voluptuous/schema_builder.py", line 432, in validate_mapping
    raise er.MultipleInvalid(errors)
voluptuous.error.MultipleInvalid: value must be at most 100 for dictionary value @ data['brightness_pct']
2022-02-16 16:12:50 ERROR (MainThread) [homeassistant] Error doing job: Task exception was never retrieved
Traceback (most recent call last):
  File "/usr/src/homeassistant/homeassistant/core.py", line 1584, in async_call
    processed_data: dict[str, Any] = handler.schema(service_data)
  File "/usr/local/lib/python3.9/site-packages/voluptuous/validators.py", line 218, in __call__
    return self._exec((Schema(val) for val in self.validators), v)
  File "/usr/local/lib/python3.9/site-packages/voluptuous/validators.py", line 341, in _exec
    raise e if self.msg is None else AllInvalid(self.msg, path=path)
  File "/usr/local/lib/python3.9/site-packages/voluptuous/validators.py", line 337, in _exec
    v = func(v)
  File "/usr/local/lib/python3.9/site-packages/voluptuous/schema_builder.py", line 272, in __call__
    return self._compiled([], data)
  File "/usr/local/lib/python3.9/site-packages/voluptuous/schema_builder.py", line 817, in validate_callable
    return schema(data)
  File "/usr/local/lib/python3.9/site-packages/voluptuous/schema_builder.py", line 272, in __call__
    return self._compiled([], data)
  File "/usr/local/lib/python3.9/site-packages/voluptuous/validators.py", line 215, in _run
    return self._exec(self._compiled, value, path)
  File "/usr/local/lib/python3.9/site-packages/voluptuous/validators.py", line 341, in _exec
    raise e if self.msg is None else AllInvalid(self.msg, path=path)
  File "/usr/local/lib/python3.9/site-packages/voluptuous/validators.py", line 339, in _exec
    v = func(path, v)
  File "/usr/local/lib/python3.9/site-packages/voluptuous/schema_builder.py", line 817, in validate_callable
    return schema(data)
  File "/usr/local/lib/python3.9/site-packages/voluptuous/schema_builder.py", line 272, in __call__
    return self._compiled([], data)
  File "/usr/local/lib/python3.9/site-packages/voluptuous/schema_builder.py", line 594, in validate_dict
    return base_validate(path, iteritems(data), out)
  File "/usr/local/lib/python3.9/site-packages/voluptuous/schema_builder.py", line 432, in validate_mapping
    raise er.MultipleInvalid(errors)
voluptuous.error.MultipleInvalid: value must be at most 100 for dictionary value @ data['brightness_pct']
2022-02-16 16:12:50 ERROR (MainThread) [homeassistant] Error doing job: Task exception was never retrieved
Traceback (most recent call last):
  File "/usr/src/homeassistant/homeassistant/core.py", line 1584, in async_call
    processed_data: dict[str, Any] = handler.schema(service_data)
  File "/usr/local/lib/python3.9/site-packages/voluptuous/validators.py", line 218, in __call__
    return self._exec((Schema(val) for val in self.validators), v)
  File "/usr/local/lib/python3.9/site-packages/voluptuous/validators.py", line 341, in _exec
    raise e if self.msg is None else AllInvalid(self.msg, path=path)
  File "/usr/local/lib/python3.9/site-packages/voluptuous/validators.py", line 337, in _exec
    v = func(v)
  File "/usr/local/lib/python3.9/site-packages/voluptuous/schema_builder.py", line 272, in __call__
    return self._compiled([], data)
  File "/usr/local/lib/python3.9/site-packages/voluptuous/schema_builder.py", line 817, in validate_callable
    return schema(data)
  File "/usr/local/lib/python3.9/site-packages/voluptuous/schema_builder.py", line 272, in __call__
    return self._compiled([], data)
  File "/usr/local/lib/python3.9/site-packages/voluptuous/validators.py", line 215, in _run
    return self._exec(self._compiled, value, path)
  File "/usr/local/lib/python3.9/site-packages/voluptuous/validators.py", line 341, in _exec
    raise e if self.msg is None else AllInvalid(self.msg, path=path)
  File "/usr/local/lib/python3.9/site-packages/voluptuous/validators.py", line 339, in _exec
    v = func(path, v)
  File "/usr/local/lib/python3.9/site-packages/voluptuous/schema_builder.py", line 817, in validate_callable
    return schema(data)
  File "/usr/local/lib/python3.9/site-packages/voluptuous/schema_builder.py", line 272, in __call__
    return self._compiled([], data)
  File "/usr/local/lib/python3.9/site-packages/voluptuous/schema_builder.py", line 594, in validate_dict
    return base_validate(path, iteritems(data), out)
  File "/usr/local/lib/python3.9/site-packages/voluptuous/schema_builder.py", line 432, in validate_mapping
    raise er.MultipleInvalid(errors)
voluptuous.error.MultipleInvalid: value must be at most 100 for dictionary value @ data['brightness_pct']
2022-02-16 16:12:50 ERROR (MainThread) [homeassistant] Error doing job: Task exception was never retrieved
Traceback (most recent call last):
  File "/usr/src/homeassistant/homeassistant/core.py", line 1584, in async_call
    processed_data: dict[str, Any] = handler.schema(service_data)
  File "/usr/local/lib/python3.9/site-packages/voluptuous/validators.py", line 218, in __call__
    return self._exec((Schema(val) for val in self.validators), v)
  File "/usr/local/lib/python3.9/site-packages/voluptuous/validators.py", line 341, in _exec
    raise e if self.msg is None else AllInvalid(self.msg, path=path)
  File "/usr/local/lib/python3.9/site-packages/voluptuous/validators.py", line 337, in _exec
    v = func(v)
  File "/usr/local/lib/python3.9/site-packages/voluptuous/schema_builder.py", line 272, in __call__
    return self._compiled([], data)
  File "/usr/local/lib/python3.9/site-packages/voluptuous/schema_builder.py", line 817, in validate_callable
    return schema(data)
  File "/usr/local/lib/python3.9/site-packages/voluptuous/schema_builder.py", line 272, in __call__
    return self._compiled([], data)
  File "/usr/local/lib/python3.9/site-packages/voluptuous/validators.py", line 215, in _run
    return self._exec(self._compiled, value, path)
  File "/usr/local/lib/python3.9/site-packages/voluptuous/validators.py", line 341, in _exec
    raise e if self.msg is None else AllInvalid(self.msg, path=path)
  File "/usr/local/lib/python3.9/site-packages/voluptuous/validators.py", line 339, in _exec
    v = func(path, v)
  File "/usr/local/lib/python3.9/site-packages/voluptuous/schema_builder.py", line 817, in validate_callable
    return schema(data)
  File "/usr/local/lib/python3.9/site-packages/voluptuous/schema_builder.py", line 272, in __call__
    return self._compiled([], data)
  File "/usr/local/lib/python3.9/site-packages/voluptuous/schema_builder.py", line 594, in validate_dict
    return base_validate(path, iteritems(data), out)
  File "/usr/local/lib/python3.9/site-packages/voluptuous/schema_builder.py", line 432, in validate_mapping
    raise er.MultipleInvalid(errors)
voluptuous.error.MultipleInvalid: value must be at most 100 for dictionary value @ data['brightness_pct']
2022-02-16 16:12:51 ERROR (MainThread) [homeassistant] Error doing job: Task exception was never retrieved
Traceback (most recent call last):
  File "/usr/src/homeassistant/homeassistant/core.py", line 1584, in async_call
    processed_data: dict[str, Any] = handler.schema(service_data)
  File "/usr/local/lib/python3.9/site-packages/voluptuous/validators.py", line 218, in __call__
    return self._exec((Schema(val) for val in self.validators), v)
  File "/usr/local/lib/python3.9/site-packages/voluptuous/validators.py", line 341, in _exec
    raise e if self.msg is None else AllInvalid(self.msg, path=path)
  File "/usr/local/lib/python3.9/site-packages/voluptuous/validators.py", line 337, in _exec
    v = func(v)
  File "/usr/local/lib/python3.9/site-packages/voluptuous/schema_builder.py", line 272, in __call__
    return self._compiled([], data)
  File "/usr/local/lib/python3.9/site-packages/voluptuous/schema_builder.py", line 817, in validate_callable
    return schema(data)
  File "/usr/local/lib/python3.9/site-packages/voluptuous/schema_builder.py", line 272, in __call__
    return self._compiled([], data)
  File "/usr/local/lib/python3.9/site-packages/voluptuous/validators.py", line 215, in _run
    return self._exec(self._compiled, value, path)
  File "/usr/local/lib/python3.9/site-packages/voluptuous/validators.py", line 341, in _exec
    raise e if self.msg is None else AllInvalid(self.msg, path=path)
  File "/usr/local/lib/python3.9/site-packages/voluptuous/validators.py", line 339, in _exec
    v = func(path, v)
  File "/usr/local/lib/python3.9/site-packages/voluptuous/schema_builder.py", line 817, in validate_callable
    return schema(data)
  File "/usr/local/lib/python3.9/site-packages/voluptuous/schema_builder.py", line 272, in __call__
    return self._compiled([], data)
  File "/usr/local/lib/python3.9/site-packages/voluptuous/schema_builder.py", line 594, in validate_dict
    return base_validate(path, iteritems(data), out)
  File "/usr/local/lib/python3.9/site-packages/voluptuous/schema_builder.py", line 432, in validate_mapping
    raise er.MultipleInvalid(errors)
voluptuous.error.MultipleInvalid: value must be at most 100 for dictionary value @ data['brightness_pct']
2022-02-16 16:12:51 ERROR (MainThread) [homeassistant] Error doing job: Task exception was never retrieved
Traceback (most recent call last):
  File "/usr/src/homeassistant/homeassistant/core.py", line 1584, in async_call
    processed_data: dict[str, Any] = handler.schema(service_data)
  File "/usr/local/lib/python3.9/site-packages/voluptuous/validators.py", line 218, in __call__
    return self._exec((Schema(val) for val in self.validators), v)
  File "/usr/local/lib/python3.9/site-packages/voluptuous/validators.py", line 341, in _exec
    raise e if self.msg is None else AllInvalid(self.msg, path=path)
  File "/usr/local/lib/python3.9/site-packages/voluptuous/validators.py", line 337, in _exec
    v = func(v)
  File "/usr/local/lib/python3.9/site-packages/voluptuous/schema_builder.py", line 272, in __call__
    return self._compiled([], data)
  File "/usr/local/lib/python3.9/site-packages/voluptuous/schema_builder.py", line 817, in validate_callable
    return schema(data)
  File "/usr/local/lib/python3.9/site-packages/voluptuous/schema_builder.py", line 272, in __call__
    return self._compiled([], data)
  File "/usr/local/lib/python3.9/site-packages/voluptuous/validators.py", line 215, in _run
    return self._exec(self._compiled, value, path)
  File "/usr/local/lib/python3.9/site-packages/voluptuous/validators.py", line 341, in _exec
    raise e if self.msg is None else AllInvalid(self.msg, path=path)
  File "/usr/local/lib/python3.9/site-packages/voluptuous/validators.py", line 339, in _exec
    v = func(path, v)
  File "/usr/local/lib/python3.9/site-packages/voluptuous/schema_builder.py", line 817, in validate_callable
    return schema(data)
  File "/usr/local/lib/python3.9/site-packages/voluptuous/schema_builder.py", line 272, in __call__
    return self._compiled([], data)
  File "/usr/local/lib/python3.9/site-packages/voluptuous/schema_builder.py", line 594, in validate_dict
    return base_validate(path, iteritems(data), out)
  File "/usr/local/lib/python3.9/site-packages/voluptuous/schema_builder.py", line 432, in validate_mapping
    raise er.MultipleInvalid(errors)
voluptuous.error.MultipleInvalid: value must be at most 100 for dictionary value @ data['brightness_pct']
2022-02-16 16:12:51 ERROR (MainThread) [homeassistant] Error doing job: Task exception was never retrieved
Traceback (most recent call last):
  File "/usr/src/homeassistant/homeassistant/core.py", line 1584, in async_call
    processed_data: dict[str, Any] = handler.schema(service_data)
  File "/usr/local/lib/python3.9/site-packages/voluptuous/validators.py", line 218, in __call__
    return self._exec((Schema(val) for val in self.validators), v)
  File "/usr/local/lib/python3.9/site-packages/voluptuous/validators.py", line 341, in _exec
    raise e if self.msg is None else AllInvalid(self.msg, path=path)
  File "/usr/local/lib/python3.9/site-packages/voluptuous/validators.py", line 337, in _exec
    v = func(v)
  File "/usr/local/lib/python3.9/site-packages/voluptuous/schema_builder.py", line 272, in __call__
    return self._compiled([], data)
  File "/usr/local/lib/python3.9/site-packages/voluptuous/schema_builder.py", line 817, in validate_callable
    return schema(data)
  File "/usr/local/lib/python3.9/site-packages/voluptuous/schema_builder.py", line 272, in __call__
    return self._compiled([], data)
  File "/usr/local/lib/python3.9/site-packages/voluptuous/validators.py", line 215, in _run
    return self._exec(self._compiled, value, path)
  File "/usr/local/lib/python3.9/site-packages/voluptuous/validators.py", line 341, in _exec
    raise e if self.msg is None else AllInvalid(self.msg, path=path)
  File "/usr/local/lib/python3.9/site-packages/voluptuous/validators.py", line 339, in _exec
    v = func(path, v)
  File "/usr/local/lib/python3.9/site-packages/voluptuous/schema_builder.py", line 817, in validate_callable
    return schema(data)
  File "/usr/local/lib/python3.9/site-packages/voluptuous/schema_builder.py", line 272, in __call__
    return self._compiled([], data)
  File "/usr/local/lib/python3.9/site-packages/voluptuous/schema_builder.py", line 594, in validate_dict
    return base_validate(path, iteritems(data), out)
  File "/usr/local/lib/python3.9/site-packages/voluptuous/schema_builder.py", line 432, in validate_mapping
    raise er.MultipleInvalid(errors)
voluptuous.error.MultipleInvalid: value must be at most 100 for dictionary value @ data['brightness_pct']
2022-02-16 16:12:51 ERROR (MainThread) [homeassistant] Error doing job: Task exception was never retrieved
Traceback (most recent call last):
  File "/usr/src/homeassistant/homeassistant/core.py", line 1584, in async_call
    processed_data: dict[str, Any] = handler.schema(service_data)
  File "/usr/local/lib/python3.9/site-packages/voluptuous/validators.py", line 218, in __call__
    return self._exec((Schema(val) for val in self.validators), v)
  File "/usr/local/lib/python3.9/site-packages/voluptuous/validators.py", line 341, in _exec
    raise e if self.msg is None else AllInvalid(self.msg, path=path)
  File "/usr/local/lib/python3.9/site-packages/voluptuous/validators.py", line 337, in _exec
    v = func(v)
  File "/usr/local/lib/python3.9/site-packages/voluptuous/schema_builder.py", line 272, in __call__
    return self._compiled([], data)
  File "/usr/local/lib/python3.9/site-packages/voluptuous/schema_builder.py", line 817, in validate_callable
    return schema(data)
  File "/usr/local/lib/python3.9/site-packages/voluptuous/schema_builder.py", line 272, in __call__
    return self._compiled([], data)
  File "/usr/local/lib/python3.9/site-packages/voluptuous/validators.py", line 215, in _run
    return self._exec(self._compiled, value, path)
  File "/usr/local/lib/python3.9/site-packages/voluptuous/validators.py", line 341, in _exec
    raise e if self.msg is None else AllInvalid(self.msg, path=path)
  File "/usr/local/lib/python3.9/site-packages/voluptuous/validators.py", line 339, in _exec
    v = func(path, v)
  File "/usr/local/lib/python3.9/site-packages/voluptuous/schema_builder.py", line 817, in validate_callable
    return schema(data)
  File "/usr/local/lib/python3.9/site-packages/voluptuous/schema_builder.py", line 272, in __call__
    return self._compiled([], data)
  File "/usr/local/lib/python3.9/site-packages/voluptuous/schema_builder.py", line 594, in validate_dict
    return base_validate(path, iteritems(data), out)
  File "/usr/local/lib/python3.9/site-packages/voluptuous/schema_builder.py", line 432, in validate_mapping
    raise er.MultipleInvalid(errors)
voluptuous.error.MultipleInvalid: value must be at most 100 for dictionary value @ data['brightness_pct']
2022-02-16 16:12:51 ERROR (MainThread) [homeassistant] Error doing job: Task exception was never retrieved
Traceback (most recent call last):
  File "/usr/src/homeassistant/homeassistant/core.py", line 1584, in async_call
    processed_data: dict[str, Any] = handler.schema(service_data)
  File "/usr/local/lib/python3.9/site-packages/voluptuous/validators.py", line 218, in __call__
    return self._exec((Schema(val) for val in self.validators), v)
  File "/usr/local/lib/python3.9/site-packages/voluptuous/validators.py", line 341, in _exec
    raise e if self.msg is None else AllInvalid(self.msg, path=path)
  File "/usr/local/lib/python3.9/site-packages/voluptuous/validators.py", line 337, in _exec
    v = func(v)
  File "/usr/local/lib/python3.9/site-packages/voluptuous/schema_builder.py", line 272, in __call__
    return self._compiled([], data)
  File "/usr/local/lib/python3.9/site-packages/voluptuous/schema_builder.py", line 817, in validate_callable
    return schema(data)
  File "/usr/local/lib/python3.9/site-packages/voluptuous/schema_builder.py", line 272, in __call__
    return self._compiled([], data)
  File "/usr/local/lib/python3.9/site-packages/voluptuous/validators.py", line 215, in _run
    return self._exec(self._compiled, value, path)
  File "/usr/local/lib/python3.9/site-packages/voluptuous/validators.py", line 341, in _exec
    raise e if self.msg is None else AllInvalid(self.msg, path=path)
  File "/usr/local/lib/python3.9/site-packages/voluptuous/validators.py", line 339, in _exec
    v = func(path, v)
  File "/usr/local/lib/python3.9/site-packages/voluptuous/schema_builder.py", line 817, in validate_callable
    return schema(data)
  File "/usr/local/lib/python3.9/site-packages/voluptuous/schema_builder.py", line 272, in __call__
    return self._compiled([], data)
  File "/usr/local/lib/python3.9/site-packages/voluptuous/schema_builder.py", line 594, in validate_dict
    return base_validate(path, iteritems(data), out)
  File "/usr/local/lib/python3.9/site-packages/voluptuous/schema_builder.py", line 432, in validate_mapping
    raise er.MultipleInvalid(errors)
voluptuous.error.MultipleInvalid: value must be at most 100 for dictionary value @ data['brightness_pct']
2022-02-16 16:12:51 ERROR (MainThread) [homeassistant] Error doing job: Task exception was never retrieved
Traceback (most recent call last):
  File "/usr/src/homeassistant/homeassistant/core.py", line 1584, in async_call
    processed_data: dict[str, Any] = handler.schema(service_data)
  File "/usr/local/lib/python3.9/site-packages/voluptuous/validators.py", line 218, in __call__
    return self._exec((Schema(val) for val in self.validators), v)
  File "/usr/local/lib/python3.9/site-packages/voluptuous/validators.py", line 341, in _exec
    raise e if self.msg is None else AllInvalid(self.msg, path=path)
  File "/usr/local/lib/python3.9/site-packages/voluptuous/validators.py", line 337, in _exec
    v = func(v)
  File "/usr/local/lib/python3.9/site-packages/voluptuous/schema_builder.py", line 272, in __call__
    return self._compiled([], data)
  File "/usr/local/lib/python3.9/site-packages/voluptuous/schema_builder.py", line 817, in validate_callable
    return schema(data)
  File "/usr/local/lib/python3.9/site-packages/voluptuous/schema_builder.py", line 272, in __call__
    return self._compiled([], data)
  File "/usr/local/lib/python3.9/site-packages/voluptuous/validators.py", line 215, in _run
    return self._exec(self._compiled, value, path)
  File "/usr/local/lib/python3.9/site-packages/voluptuous/validators.py", line 341, in _exec
    raise e if self.msg is None else AllInvalid(self.msg, path=path)
  File "/usr/local/lib/python3.9/site-packages/voluptuous/validators.py", line 339, in _exec
    v = func(path, v)
  File "/usr/local/lib/python3.9/site-packages/voluptuous/schema_builder.py", line 817, in validate_callable
    return schema(data)
  File "/usr/local/lib/python3.9/site-packages/voluptuous/schema_builder.py", line 272, in __call__
    return self._compiled([], data)
  File "/usr/local/lib/python3.9/site-packages/voluptuous/schema_builder.py", line 594, in validate_dict
    return base_validate(path, iteritems(data), out)
  File "/usr/local/lib/python3.9/site-packages/voluptuous/schema_builder.py", line 432, in validate_mapping
    raise er.MultipleInvalid(errors)
voluptuous.error.MultipleInvalid: value must be at most 100 for dictionary value @ data['brightness_pct']
2022-02-16 16:12:51 ERROR (MainThread) [homeassistant] Error doing job: Task exception was never retrieved
Traceback (most recent call last):
  File "/usr/src/homeassistant/homeassistant/core.py", line 1584, in async_call
    processed_data: dict[str, Any] = handler.schema(service_data)
  File "/usr/local/lib/python3.9/site-packages/voluptuous/validators.py", line 218, in __call__
    return self._exec((Schema(val) for val in self.validators), v)
  File "/usr/local/lib/python3.9/site-packages/voluptuous/validators.py", line 341, in _exec
    raise e if self.msg is None else AllInvalid(self.msg, path=path)
  File "/usr/local/lib/python3.9/site-packages/voluptuous/validators.py", line 337, in _exec
    v = func(v)
  File "/usr/local/lib/python3.9/site-packages/voluptuous/schema_builder.py", line 272, in __call__
    return self._compiled([], data)
  File "/usr/local/lib/python3.9/site-packages/voluptuous/schema_builder.py", line 817, in validate_callable
    return schema(data)
  File "/usr/local/lib/python3.9/site-packages/voluptuous/schema_builder.py", line 272, in __call__
    return self._compiled([], data)
  File "/usr/local/lib/python3.9/site-packages/voluptuous/validators.py", line 215, in _run
    return self._exec(self._compiled, value, path)
  File "/usr/local/lib/python3.9/site-packages/voluptuous/validators.py", line 341, in _exec
    raise e if self.msg is None else AllInvalid(self.msg, path=path)
  File "/usr/local/lib/python3.9/site-packages/voluptuous/validators.py", line 339, in _exec
    v = func(path, v)
  File "/usr/local/lib/python3.9/site-packages/voluptuous/schema_builder.py", line 817, in validate_callable
    return schema(data)
  File "/usr/local/lib/python3.9/site-packages/voluptuous/schema_builder.py", line 272, in __call__
    return self._compiled([], data)
  File "/usr/local/lib/python3.9/site-packages/voluptuous/schema_builder.py", line 594, in validate_dict
    return base_validate(path, iteritems(data), out)
  File "/usr/local/lib/python3.9/site-packages/voluptuous/schema_builder.py", line 432, in validate_mapping
    raise er.MultipleInvalid(errors)
voluptuous.error.MultipleInvalid: value must be at most 100 for dictionary value @ data['brightness_pct']
2022-02-16 16:12:52 ERROR (MainThread) [homeassistant] Error doing job: Task exception was never retrieved
Traceback (most recent call last):
  File "/usr/src/homeassistant/homeassistant/core.py", line 1584, in async_call
    processed_data: dict[str, Any] = handler.schema(service_data)
  File "/usr/local/lib/python3.9/site-packages/voluptuous/validators.py", line 218, in __call__
    return self._exec((Schema(val) for val in self.validators), v)
  File "/usr/local/lib/python3.9/site-packages/voluptuous/validators.py", line 341, in _exec
    raise e if self.msg is None else AllInvalid(self.msg, path=path)
  File "/usr/local/lib/python3.9/site-packages/voluptuous/validators.py", line 337, in _exec
    v = func(v)
  File "/usr/local/lib/python3.9/site-packages/voluptuous/schema_builder.py", line 272, in __call__
    return self._compiled([], data)
  File "/usr/local/lib/python3.9/site-packages/voluptuous/schema_builder.py", line 817, in validate_callable
    return schema(data)
  File "/usr/local/lib/python3.9/site-packages/voluptuous/schema_builder.py", line 272, in __call__
    return self._compiled([], data)
  File "/usr/local/lib/python3.9/site-packages/voluptuous/validators.py", line 215, in _run
    return self._exec(self._compiled, value, path)
  File "/usr/local/lib/python3.9/site-packages/voluptuous/validators.py", line 341, in _exec
    raise e if self.msg is None else AllInvalid(self.msg, path=path)
  File "/usr/local/lib/python3.9/site-packages/voluptuous/validators.py", line 339, in _exec
    v = func(path, v)
  File "/usr/local/lib/python3.9/site-packages/voluptuous/schema_builder.py", line 817, in validate_callable
    return schema(data)
  File "/usr/local/lib/python3.9/site-packages/voluptuous/schema_builder.py", line 272, in __call__
    return self._compiled([], data)
  File "/usr/local/lib/python3.9/site-packages/voluptuous/schema_builder.py", line 594, in validate_dict
    return base_validate(path, iteritems(data), out)
  File "/usr/local/lib/python3.9/site-packages/voluptuous/schema_builder.py", line 432, in validate_mapping
    raise er.MultipleInvalid(errors)
voluptuous.error.MultipleInvalid: value must be at most 100 for dictionary value @ data['brightness_pct']
2022-02-16 16:12:52 ERROR (MainThread) [homeassistant] Error doing job: Task exception was never retrieved
Traceback (most recent call last):
  File "/usr/src/homeassistant/homeassistant/core.py", line 1584, in async_call
    processed_data: dict[str, Any] = handler.schema(service_data)
  File "/usr/local/lib/python3.9/site-packages/voluptuous/validators.py", line 218, in __call__
    return self._exec((Schema(val) for val in self.validators), v)
  File "/usr/local/lib/python3.9/site-packages/voluptuous/validators.py", line 341, in _exec
    raise e if self.msg is None else AllInvalid(self.msg, path=path)
  File "/usr/local/lib/python3.9/site-packages/voluptuous/validators.py", line 337, in _exec
    v = func(v)
  File "/usr/local/lib/python3.9/site-packages/voluptuous/schema_builder.py", line 272, in __call__
    return self._compiled([], data)
  File "/usr/local/lib/python3.9/site-packages/voluptuous/schema_builder.py", line 817, in validate_callable
    return schema(data)
  File "/usr/local/lib/python3.9/site-packages/voluptuous/schema_builder.py", line 272, in __call__
    return self._compiled([], data)
  File "/usr/local/lib/python3.9/site-packages/voluptuous/validators.py", line 215, in _run
    return self._exec(self._compiled, value, path)
  File "/usr/local/lib/python3.9/site-packages/voluptuous/validators.py", line 341, in _exec
    raise e if self.msg is None else AllInvalid(self.msg, path=path)
  File "/usr/local/lib/python3.9/site-packages/voluptuous/validators.py", line 339, in _exec
    v = func(path, v)
  File "/usr/local/lib/python3.9/site-packages/voluptuous/schema_builder.py", line 817, in validate_callable
    return schema(data)
  File "/usr/local/lib/python3.9/site-packages/voluptuous/schema_builder.py", line 272, in __call__
    return self._compiled([], data)
  File "/usr/local/lib/python3.9/site-packages/voluptuous/schema_builder.py", line 594, in validate_dict
    return base_validate(path, iteritems(data), out)
  File "/usr/local/lib/python3.9/site-packages/voluptuous/schema_builder.py", line 432, in validate_mapping
    raise er.MultipleInvalid(errors)
voluptuous.error.MultipleInvalid: value must be at most 100 for dictionary value @ data['brightness_pct']
2022-02-16 16:12:52 ERROR (MainThread) [homeassistant] Error doing job: Task exception was never retrieved
Traceback (most recent call last):
  File "/usr/src/homeassistant/homeassistant/core.py", line 1584, in async_call
    processed_data: dict[str, Any] = handler.schema(service_data)
  File "/usr/local/lib/python3.9/site-packages/voluptuous/validators.py", line 218, in __call__
    return self._exec((Schema(val) for val in self.validators), v)
  File "/usr/local/lib/python3.9/site-packages/voluptuous/validators.py", line 341, in _exec
    raise e if self.msg is None else AllInvalid(self.msg, path=path)
  File "/usr/local/lib/python3.9/site-packages/voluptuous/validators.py", line 337, in _exec
    v = func(v)
  File "/usr/local/lib/python3.9/site-packages/voluptuous/schema_builder.py", line 272, in __call__
    return self._compiled([], data)
  File "/usr/local/lib/python3.9/site-packages/voluptuous/schema_builder.py", line 817, in validate_callable
    return schema(data)
  File "/usr/local/lib/python3.9/site-packages/voluptuous/schema_builder.py", line 272, in __call__
    return self._compiled([], data)
  File "/usr/local/lib/python3.9/site-packages/voluptuous/validators.py", line 215, in _run
    return self._exec(self._compiled, value, path)
  File "/usr/local/lib/python3.9/site-packages/voluptuous/validators.py", line 341, in _exec
    raise e if self.msg is None else AllInvalid(self.msg, path=path)
  File "/usr/local/lib/python3.9/site-packages/voluptuous/validators.py", line 339, in _exec
    v = func(path, v)
  File "/usr/local/lib/python3.9/site-packages/voluptuous/schema_builder.py", line 817, in validate_callable
    return schema(data)
  File "/usr/local/lib/python3.9/site-packages/voluptuous/schema_builder.py", line 272, in __call__
    return self._compiled([], data)
  File "/usr/local/lib/python3.9/site-packages/voluptuous/schema_builder.py", line 594, in validate_dict
    return base_validate(path, iteritems(data), out)
  File "/usr/local/lib/python3.9/site-packages/voluptuous/schema_builder.py", line 432, in validate_mapping
    raise er.MultipleInvalid(errors)
voluptuous.error.MultipleInvalid: value must be at most 100 for dictionary value @ data['brightness_pct']
2022-02-16 16:12:52 ERROR (MainThread) [homeassistant] Error doing job: Task exception was never retrieved
Traceback (most recent call last):
  File "/usr/src/homeassistant/homeassistant/core.py", line 1584, in async_call
    processed_data: dict[str, Any] = handler.schema(service_data)
  File "/usr/local/lib/python3.9/site-packages/voluptuous/validators.py", line 218, in __call__
    return self._exec((Schema(val) for val in self.validators), v)
  File "/usr/local/lib/python3.9/site-packages/voluptuous/validators.py", line 341, in _exec
    raise e if self.msg is None else AllInvalid(self.msg, path=path)
  File "/usr/local/lib/python3.9/site-packages/voluptuous/validators.py", line 337, in _exec
    v = func(v)
  File "/usr/local/lib/python3.9/site-packages/voluptuous/schema_builder.py", line 272, in __call__
    return self._compiled([], data)
  File "/usr/local/lib/python3.9/site-packages/voluptuous/schema_builder.py", line 817, in validate_callable
    return schema(data)
  File "/usr/local/lib/python3.9/site-packages/voluptuous/schema_builder.py", line 272, in __call__
    return self._compiled([], data)
  File "/usr/local/lib/python3.9/site-packages/voluptuous/validators.py", line 215, in _run
    return self._exec(self._compiled, value, path)
  File "/usr/local/lib/python3.9/site-packages/voluptuous/validators.py", line 341, in _exec
    raise e if self.msg is None else AllInvalid(self.msg, path=path)
  File "/usr/local/lib/python3.9/site-packages/voluptuous/validators.py", line 339, in _exec
    v = func(path, v)
  File "/usr/local/lib/python3.9/site-packages/voluptuous/schema_builder.py", line 817, in validate_callable
    return schema(data)
  File "/usr/local/lib/python3.9/site-packages/voluptuous/schema_builder.py", line 272, in __call__
    return self._compiled([], data)
  File "/usr/local/lib/python3.9/site-packages/voluptuous/schema_builder.py", line 594, in validate_dict
    return base_validate(path, iteritems(data), out)
  File "/usr/local/lib/python3.9/site-packages/voluptuous/schema_builder.py", line 432, in validate_mapping
    raise er.MultipleInvalid(errors)
voluptuous.error.MultipleInvalid: value must be at most 100 for dictionary value @ data['brightness_pct']
2022-02-16 16:12:52 ERROR (MainThread) [homeassistant] Error doing job: Task exception was never retrieved
Traceback (most recent call last):
  File "/usr/src/homeassistant/homeassistant/core.py", line 1584, in async_call
    processed_data: dict[str, Any] = handler.schema(service_data)
  File "/usr/local/lib/python3.9/site-packages/voluptuous/validators.py", line 218, in __call__
    return self._exec((Schema(val) for val in self.validators), v)
  File "/usr/local/lib/python3.9/site-packages/voluptuous/validators.py", line 341, in _exec
    raise e if self.msg is None else AllInvalid(self.msg, path=path)
  File "/usr/local/lib/python3.9/site-packages/voluptuous/validators.py", line 337, in _exec
    v = func(v)
  File "/usr/local/lib/python3.9/site-packages/voluptuous/schema_builder.py", line 272, in __call__
    return self._compiled([], data)
  File "/usr/local/lib/python3.9/site-packages/voluptuous/schema_builder.py", line 817, in validate_callable
    return schema(data)
  File "/usr/local/lib/python3.9/site-packages/voluptuous/schema_builder.py", line 272, in __call__
    return self._compiled([], data)
  File "/usr/local/lib/python3.9/site-packages/voluptuous/validators.py", line 215, in _run
    return self._exec(self._compiled, value, path)
  File "/usr/local/lib/python3.9/site-packages/voluptuous/validators.py", line 341, in _exec
    raise e if self.msg is None else AllInvalid(self.msg, path=path)
  File "/usr/local/lib/python3.9/site-packages/voluptuous/validators.py", line 339, in _exec
    v = func(path, v)
  File "/usr/local/lib/python3.9/site-packages/voluptuous/schema_builder.py", line 817, in validate_callable
    return schema(data)
  File "/usr/local/lib/python3.9/site-packages/voluptuous/schema_builder.py", line 272, in __call__
    return self._compiled([], data)
  File "/usr/local/lib/python3.9/site-packages/voluptuous/schema_builder.py", line 594, in validate_dict
    return base_validate(path, iteritems(data), out)
  File "/usr/local/lib/python3.9/site-packages/voluptuous/schema_builder.py", line 432, in validate_mapping
    raise er.MultipleInvalid(errors)
voluptuous.error.MultipleInvalid: value must be at most 100 for dictionary value @ data['brightness_pct']
2022-02-16 16:12:53 ERROR (MainThread) [homeassistant] Error doing job: Task exception was never retrieved
Traceback (most recent call last):
  File "/usr/src/homeassistant/homeassistant/core.py", line 1584, in async_call
    processed_data: dict[str, Any] = handler.schema(service_data)
  File "/usr/local/lib/python3.9/site-packages/voluptuous/validators.py", line 218, in __call__
    return self._exec((Schema(val) for val in self.validators), v)
  File "/usr/local/lib/python3.9/site-packages/voluptuous/validators.py", line 341, in _exec
    raise e if self.msg is None else AllInvalid(self.msg, path=path)
  File "/usr/local/lib/python3.9/site-packages/voluptuous/validators.py", line 337, in _exec
    v = func(v)
  File "/usr/local/lib/python3.9/site-packages/voluptuous/schema_builder.py", line 272, in __call__
    return self._compiled([], data)
  File "/usr/local/lib/python3.9/site-packages/voluptuous/schema_builder.py", line 817, in validate_callable
    return schema(data)
  File "/usr/local/lib/python3.9/site-packages/voluptuous/schema_builder.py", line 272, in __call__
    return self._compiled([], data)
  File "/usr/local/lib/python3.9/site-packages/voluptuous/validators.py", line 215, in _run
    return self._exec(self._compiled, value, path)
  File "/usr/local/lib/python3.9/site-packages/voluptuous/validators.py", line 341, in _exec
    raise e if self.msg is None else AllInvalid(self.msg, path=path)
  File "/usr/local/lib/python3.9/site-packages/voluptuous/validators.py", line 339, in _exec
    v = func(path, v)
  File "/usr/local/lib/python3.9/site-packages/voluptuous/schema_builder.py", line 817, in validate_callable
    return schema(data)
  File "/usr/local/lib/python3.9/site-packages/voluptuous/schema_builder.py", line 272, in __call__
    return self._compiled([], data)
  File "/usr/local/lib/python3.9/site-packages/voluptuous/schema_builder.py", line 594, in validate_dict
    return base_validate(path, iteritems(data), out)
  File "/usr/local/lib/python3.9/site-packages/voluptuous/schema_builder.py", line 432, in validate_mapping
    raise er.MultipleInvalid(errors)
voluptuous.error.MultipleInvalid: value must be at most 100 for dictionary value @ data['brightness_pct']
2022-02-16 16:13:34 ERROR (SyncWorker_5) [spotipy.client] HTTP Error for GET to https://api.spotify.com/v1/me/player/devices with Params: {} returned 401 due to The access token expired
2022-02-16 16:18:34 ERROR (SyncWorker_13) [spotipy.client] HTTP Error for GET to https://api.spotify.com/v1/me/player/devices with Params: {} returned 401 due to The access token expired
2022-02-16 16:23:34 ERROR (SyncWorker_3) [spotipy.client] HTTP Error for GET to https://api.spotify.com/v1/me/player/devices with Params: {} returned 401 due to The access token expired
2022-02-16 16:24:55 WARNING (MainThread) [homeassistant.helpers.service] Unable to find referenced entities scene.warning_lights
2022-02-16 16:24:55 WARNING (MainThread) [homeassistant.helpers.service] Unable to find referenced entities scene.all_lights
2022-02-16 16:28:19 WARNING (Thread-710) [custom_components.aquaariston.aristonaqua] <custom_components.aquaariston.aristonaqua.AquaAristonHandler object at 0x149dcf2f60a0> _get_cleanse invalid reply code 500
2022-02-16 16:28:19 WARNING (Thread-710) [custom_components.aquaariston.aristonaqua] ariston action nok for _get_cleanse: Unexpected code 500 received for the request _get_cleanse
2022-02-16 16:28:34 ERROR (SyncWorker_12) [spotipy.client] HTTP Error for GET to https://api.spotify.com/v1/me/player/devices with Params: {} returned 401 due to The access token expired
2022-02-16 16:28:45 WARNING (Thread-712) [custom_components.aquaariston.aristonaqua] <custom_components.aquaariston.aristonaqua.AquaAristonHandler object at 0x149dcf2f60a0> _get_error Problem reading data
2022-02-16 16:28:45 WARNING (Thread-712) [custom_components.aquaariston.aristonaqua] ariston action nok for _get_error: Request _get_error has failed with an exception
2022-02-16 16:29:15 WARNING (Thread-714) [custom_components.aquaariston.aristonaqua] <custom_components.aquaariston.aristonaqua.AquaAristonHandler object at 0x149dcf2f60a0> _get_time_prog Problem reading data
2022-02-16 16:29:15 WARNING (Thread-714) [custom_components.aquaariston.aristonaqua] ariston action nok for _get_time_prog: Request _get_time_prog has failed with an exception
2022-02-16 16:30:03 WARNING (Thread-717) [custom_components.aquaariston.aristonaqua] <custom_components.aquaariston.aristonaqua.AquaAristonHandler object at 0x149dcf2f60a0> _get_main Problem reading data
2022-02-16 16:30:03 WARNING (Thread-717) [custom_components.aquaariston.aristonaqua] Connection errors: 1
2022-02-16 16:30:03 WARNING (Thread-717) [custom_components.aquaariston.aristonaqua] ariston action nok for _get_main: Request _get_main has failed with an exception
2022-02-16 16:30:27 WARNING (Thread-719) [custom_components.aquaariston.aristonaqua] <custom_components.aquaariston.aristonaqua.AquaAristonHandler object at 0x149dcf2f60a0> _get_main Problem reading data
2022-02-16 16:30:27 WARNING (Thread-719) [custom_components.aquaariston.aristonaqua] Connection errors: 2
2022-02-16 16:30:27 WARNING (Thread-719) [custom_components.aquaariston.aristonaqua] ariston action nok for _get_main: Request _get_main has failed with an exception
2022-02-16 16:32:27 WARNING (Thread-729) [custom_components.aquaariston.aristonaqua] <custom_components.aquaariston.aristonaqua.AquaAristonHandler object at 0x149dcf2f60a0> _get_use Problem reading data
2022-02-16 16:32:27 WARNING (Thread-729) [custom_components.aquaariston.aristonaqua] ariston action nok for _get_use: Request _get_use has failed with an exception
2022-02-16 16:33:34 ERROR (SyncWorker_13) [spotipy.client] HTTP Error for GET to https://api.spotify.com/v1/me/player/devices with Params: {} returned 401 due to The access token expired
2022-02-16 16:38:34 ERROR (SyncWorker_4) [spotipy.client] HTTP Error for GET to https://api.spotify.com/v1/me/player/devices with Params: {} returned 401 due to The access token expired
2022-02-16 16:39:00 INFO (MainThread) [backoff] Backing off fetch_events(...) for 0.2s (pyoverkiz.exceptions.InvalidEventListenerIdException: Invalid event listener id : 02f8de47-98e4-e192-403a-40595c73a4fa)
2022-02-16 16:39:14 ERROR (MainThread) [frontend.js.latest.202202030] http://192.168.1.79:8123/frontend_latest/729f9b9d.js:1:351 Uncaught RangeError: Value need to be finite number for Intl.RelativeTimeFormat.prototype.format()
2022-02-16 16:39:16 ERROR (MainThread) [frontend.js.latest.202202030] http://192.168.1.79:8123/frontend_latest/729f9b9d.js:1:351 Uncaught RangeError: Value need to be finite number for Intl.RelativeTimeFormat.prototype.format()
2022-02-16 16:41:22 ERROR (MainThread) [frontend.js.latest.202202030] http://192.168.1.79:8123/frontend_latest/729f9b9d.js:1:351 Uncaught RangeError: Value need to be finite number for Intl.RelativeTimeFormat.prototype.format()
2022-02-16 16:41:52 ERROR (MainThread) [aiohttp.server] Error handling request
Traceback (most recent call last):
  File "/usr/local/lib/python3.9/site-packages/aiohttp/web_protocol.py", line 435, in _handle_request
    resp = await request_handler(request)
  File "/usr/local/lib/python3.9/site-packages/aiohttp/web_app.py", line 504, in _handle
    resp = await handler(request)
  File "/usr/local/lib/python3.9/site-packages/aiohttp/web_middlewares.py", line 117, in impl
    return await handler(request)
  File "/usr/src/homeassistant/homeassistant/components/http/security_filter.py", line 60, in security_filter_middleware
    return await handler(request)
  File "/usr/src/homeassistant/homeassistant/components/http/forwarded.py", line 98, in forwarded_middleware
    return await handler(request)
  File "/usr/src/homeassistant/homeassistant/components/http/request_context.py", line 28, in request_context_middleware
    return await handler(request)
  File "/usr/src/homeassistant/homeassistant/components/http/ban.py", line 79, in ban_middleware
    return await handler(request)
  File "/usr/src/homeassistant/homeassistant/components/http/auth.py", line 219, in auth_middleware
    return await handler(request)
  File "/usr/src/homeassistant/homeassistant/components/http/view.py", line 137, in handle
    result = await result
  File "/usr/src/homeassistant/homeassistant/components/image/__init__.py", line 194, in get
    await hass.async_add_executor_job(
  File "/usr/local/lib/python3.9/concurrent/futures/thread.py", line 52, in run
    result = self.fn(*self.args, **self.kwargs)
  File "/usr/src/homeassistant/homeassistant/components/image/__init__.py", line 210, in _generate_thumbnail
    image = ImageOps.exif_transpose(Image.open(original_path))
  File "/usr/local/lib/python3.9/site-packages/PIL/Image.py", line 2953, in open
    fp = builtins.open(filename, "rb")
FileNotFoundError: [Errno 2] No such file or directory: '/config/image/b46152742f1a261655cb02d8e9e671e5/original'
2022-02-16 16:42:32 ERROR (MainThread) [frontend.js.latest.202202030] http://192.168.1.79:8123/frontend_latest/729f9b9d.js:1:351 Uncaught RangeError: Value need to be finite number for Intl.RelativeTimeFormat.prototype.format()
2022-02-16 16:43:34 ERROR (SyncWorker_1) [spotipy.client] HTTP Error for GET to https://api.spotify.com/v1/me/player/devices with Params: {} returned 401 due to The access token expired
2022-02-16 16:47:24 ERROR (SyncWorker_4) [pyicloud.base] Authentication required for Account. (421)
2022-02-16 16:48:34 ERROR (SyncWorker_2) [spotipy.client] HTTP Error for GET to https://api.spotify.com/v1/me/player/devices with Params: {} returned 401 due to The access token expired
2022-02-16 16:50:53 ERROR (MainThread) [homeassistant.components.websocket_api.http.connection] [22667198265520] Error handling message: Unknown error
Traceback (most recent call last):
  File "/usr/src/homeassistant/homeassistant/components/websocket_api/connection.py", line 107, in async_handle
    handler(self.hass, self, schema(msg))
  File "/usr/src/homeassistant/homeassistant/components/search/__init__.py", line 54, in websocket_search_related
    msg["id"], searcher.async_search(msg["item_type"], msg["item_id"])
  File "/usr/src/homeassistant/homeassistant/components/search/__init__.py", line 96, in async_search
    getattr(self, f"_resolve_{search_type}")(search_id)
  File "/usr/src/homeassistant/homeassistant/components/search/__init__.py", line 166, in _resolve_device
    for entity_id in automation.automations_with_device(self.hass, device_id):
  File "/usr/src/homeassistant/homeassistant/components/automation/__init__.py", line 175, in automations_with_device
    return [
  File "/usr/src/homeassistant/homeassistant/components/automation/__init__.py", line 178, in <listcomp>
    if device_id in automation_entity.referenced_devices
  File "/usr/src/homeassistant/homeassistant/components/automation/__init__.py", line 348, in referenced_devices
    referenced = self.action_script.referenced_devices
  File "/usr/src/homeassistant/homeassistant/helpers/script.py", line 1105, in referenced_devices
    Script._find_referenced_devices(self._referenced_devices, self.sequence)
  File "/usr/src/homeassistant/homeassistant/helpers/script.py", line 1119, in _find_referenced_devices
    _referenced_extract_ids(data, ATTR_DEVICE_ID, referenced)
  File "/usr/src/homeassistant/homeassistant/helpers/script.py", line 926, in _referenced_extract_ids
    item_ids = data.get(key)
AttributeError: 'Template' object has no attribute 'get'
2022-02-16 16:51:09 ERROR (SyncWorker_6) [pyicloud.base] Authentication required for Account. (421)
2022-02-16 16:51:28 WARNING (SyncWorker_13) [pyicloud.base.http] Failed to parse response with JSON mimetype
2022-02-16 16:52:31 WARNING (MainThread) [homeassistant.helpers.template] Template variable warning: 'source' is undefined when rendering '{{ source }}'
2022-02-16 16:52:31 ERROR (MainThread) [homeassistant.components.denonavr.media_player] Command async_select_source failed with error: No mapping for input source 
2022-02-16 16:53:14 ERROR (MainThread) [homeassistant.components.websocket_api.http.connection] [22667198265520] Error handling message: Unknown error
Traceback (most recent call last):
  File "/usr/src/homeassistant/homeassistant/components/websocket_api/connection.py", line 107, in async_handle
    handler(self.hass, self, schema(msg))
  File "/usr/src/homeassistant/homeassistant/components/search/__init__.py", line 54, in websocket_search_related
    msg["id"], searcher.async_search(msg["item_type"], msg["item_id"])
  File "/usr/src/homeassistant/homeassistant/components/search/__init__.py", line 96, in async_search
    getattr(self, f"_resolve_{search_type}")(search_id)
  File "/usr/src/homeassistant/homeassistant/components/search/__init__.py", line 180, in _resolve_entity
    for entity in automation.automations_with_entity(self.hass, entity_id):
  File "/usr/src/homeassistant/homeassistant/components/automation/__init__.py", line 146, in automations_with_entity
    return [
  File "/usr/src/homeassistant/homeassistant/components/automation/__init__.py", line 149, in <listcomp>
    if entity_id in automation_entity.referenced_entities
  File "/usr/src/homeassistant/homeassistant/components/automation/__init__.py", line 368, in referenced_entities
    referenced = self.action_script.referenced_entities
  File "/usr/src/homeassistant/homeassistant/helpers/script.py", line 1142, in referenced_entities
    Script._find_referenced_entities(self._referenced_entities, self.sequence)
  File "/usr/src/homeassistant/homeassistant/helpers/script.py", line 1157, in _find_referenced_entities
    _referenced_extract_ids(data, ATTR_ENTITY_ID, referenced)
  File "/usr/src/homeassistant/homeassistant/helpers/script.py", line 926, in _referenced_extract_ids
    item_ids = data.get(key)
AttributeError: 'Template' object has no attribute 'get'
2022-02-16 16:53:33 ERROR (MainThread) [frontend.js.latest.202202030] http://192.168.1.79:8123/frontend_latest/729f9b9d.js:1:351 Uncaught RangeError: Value need to be finite number for Intl.RelativeTimeFormat.prototype.format()
2022-02-16 16:53:34 ERROR (SyncWorker_10) [spotipy.client] HTTP Error for GET to https://api.spotify.com/v1/me/player/devices with Params: {} returned 401 due to The access token expired
2022-02-16 16:58:34 ERROR (SyncWorker_10) [spotipy.client] HTTP Error for GET to https://api.spotify.com/v1/me/player/devices with Params: {} returned 401 due to The access token expired
2022-02-16 17:02:16 ERROR (MainThread) [homeassistant.config] Invalid config for [automation]: required key not provided @ data['trigger'][0]['platform']. Got None. (See /config/configuration.yaml, line 57). 
2022-02-16 17:02:40 ERROR (MainThread) [homeassistant.config] Invalid config for [automation]: required key not provided @ data['trigger'][0]['platform']. Got None. (See /config/configuration.yaml, line 57). 
2022-02-16 17:03:34 ERROR (SyncWorker_9) [spotipy.client] HTTP Error for GET to https://api.spotify.com/v1/me/player/devices with Params: {} returned 401 due to The access token expired
2022-02-16 17:04:30 ERROR (MainThread) [homeassistant.config] Invalid config for [automation]: required key not provided @ data['trigger'][0]['platform']. Got None. (See /config/configuration.yaml, line 57). 
